{
 "cells": [
  {
   "cell_type": "code",
   "execution_count": 1,
   "id": "3c1429d8",
   "metadata": {},
   "outputs": [],
   "source": [
    "import h2o"
   ]
  },
  {
   "cell_type": "code",
   "execution_count": 3,
   "id": "43f90618",
   "metadata": {},
   "outputs": [
    {
     "name": "stdout",
     "output_type": "stream",
     "text": [
      "Checking whether there is an H2O instance running at http://localhost:54321 ..... not found.\n",
      "Attempting to start a local H2O server...\n",
      "; Java HotSpot(TM) 64-Bit Server VM 18.9 (build 11.0.11+9-LTS-194, mixed mode)\n",
      "  Starting server from C:\\Users\\Admin\\anaconda3\\Lib\\site-packages\\h2o\\backend\\bin\\h2o.jar\n",
      "  Ice root: C:\\Users\\Admin\\AppData\\Local\\Temp\\tmp58ynkrzx\n",
      "  JVM stdout: C:\\Users\\Admin\\AppData\\Local\\Temp\\tmp58ynkrzx\\h2o_Admin_started_from_python.out\n",
      "  JVM stderr: C:\\Users\\Admin\\AppData\\Local\\Temp\\tmp58ynkrzx\\h2o_Admin_started_from_python.err\n",
      "  Server is running at http://127.0.0.1:54321\n",
      "Connecting to H2O server at http://127.0.0.1:54321 ... successful.\n"
     ]
    },
    {
     "data": {
      "text/html": [
       "<div style=\"overflow:auto\"><table style=\"width:50%\"><tr><td>H2O_cluster_uptime:</td>\n",
       "<td>05 secs</td></tr>\n",
       "<tr><td>H2O_cluster_timezone:</td>\n",
       "<td>Asia/Kolkata</td></tr>\n",
       "<tr><td>H2O_data_parsing_timezone:</td>\n",
       "<td>UTC</td></tr>\n",
       "<tr><td>H2O_cluster_version:</td>\n",
       "<td>3.32.1.4</td></tr>\n",
       "<tr><td>H2O_cluster_version_age:</td>\n",
       "<td>23 days </td></tr>\n",
       "<tr><td>H2O_cluster_name:</td>\n",
       "<td>H2O_from_python_Admin_vbs6xn</td></tr>\n",
       "<tr><td>H2O_cluster_total_nodes:</td>\n",
       "<td>1</td></tr>\n",
       "<tr><td>H2O_cluster_free_memory:</td>\n",
       "<td>2.967 Gb</td></tr>\n",
       "<tr><td>H2O_cluster_total_cores:</td>\n",
       "<td>4</td></tr>\n",
       "<tr><td>H2O_cluster_allowed_cores:</td>\n",
       "<td>4</td></tr>\n",
       "<tr><td>H2O_cluster_status:</td>\n",
       "<td>accepting new members, healthy</td></tr>\n",
       "<tr><td>H2O_connection_url:</td>\n",
       "<td>http://127.0.0.1:54321</td></tr>\n",
       "<tr><td>H2O_connection_proxy:</td>\n",
       "<td>{\"http\": null, \"https\": null}</td></tr>\n",
       "<tr><td>H2O_internal_security:</td>\n",
       "<td>False</td></tr>\n",
       "<tr><td>H2O_API_Extensions:</td>\n",
       "<td>Amazon S3, Algos, AutoML, Core V3, TargetEncoder, Core V4</td></tr>\n",
       "<tr><td>Python_version:</td>\n",
       "<td>3.8.8 final</td></tr></table></div>"
      ],
      "text/plain": [
       "--------------------------  ---------------------------------------------------------\n",
       "H2O_cluster_uptime:         05 secs\n",
       "H2O_cluster_timezone:       Asia/Kolkata\n",
       "H2O_data_parsing_timezone:  UTC\n",
       "H2O_cluster_version:        3.32.1.4\n",
       "H2O_cluster_version_age:    23 days\n",
       "H2O_cluster_name:           H2O_from_python_Admin_vbs6xn\n",
       "H2O_cluster_total_nodes:    1\n",
       "H2O_cluster_free_memory:    2.967 Gb\n",
       "H2O_cluster_total_cores:    4\n",
       "H2O_cluster_allowed_cores:  4\n",
       "H2O_cluster_status:         accepting new members, healthy\n",
       "H2O_connection_url:         http://127.0.0.1:54321\n",
       "H2O_connection_proxy:       {\"http\": null, \"https\": null}\n",
       "H2O_internal_security:      False\n",
       "H2O_API_Extensions:         Amazon S3, Algos, AutoML, Core V3, TargetEncoder, Core V4\n",
       "Python_version:             3.8.8 final\n",
       "--------------------------  ---------------------------------------------------------"
      ]
     },
     "metadata": {},
     "output_type": "display_data"
    }
   ],
   "source": [
    "h2o.init()"
   ]
  },
  {
   "cell_type": "code",
   "execution_count": 4,
   "id": "7149c7dd",
   "metadata": {},
   "outputs": [
    {
     "name": "stdout",
     "output_type": "stream",
     "text": [
      "Parse progress: |█████████████████████████████████████████████████████████| 100%\n"
     ]
    },
    {
     "data": {
      "text/plain": [
       "['V1',\n",
       " 'V2',\n",
       " 'V3',\n",
       " 'V4',\n",
       " 'V5',\n",
       " 'V6',\n",
       " 'V7',\n",
       " 'V8',\n",
       " 'V9',\n",
       " 'V10',\n",
       " 'V11',\n",
       " 'V12',\n",
       " 'V13',\n",
       " 'V14',\n",
       " 'V15',\n",
       " 'V16',\n",
       " 'V17',\n",
       " 'V18',\n",
       " 'V19',\n",
       " 'V20',\n",
       " 'V21',\n",
       " 'V22',\n",
       " 'V23',\n",
       " 'V24',\n",
       " 'V25',\n",
       " 'V26',\n",
       " 'V27',\n",
       " 'V28',\n",
       " 'V29',\n",
       " 'V30',\n",
       " 'V31',\n",
       " 'V32',\n",
       " 'V33',\n",
       " 'V34',\n",
       " 'V35',\n",
       " 'V36',\n",
       " 'V37',\n",
       " 'V38',\n",
       " 'V39',\n",
       " 'V40',\n",
       " 'V41',\n",
       " 'V42',\n",
       " 'V43',\n",
       " 'V44',\n",
       " 'V45',\n",
       " 'V46',\n",
       " 'V47',\n",
       " 'V48',\n",
       " 'V49',\n",
       " 'V50',\n",
       " 'V51',\n",
       " 'V52',\n",
       " 'V53',\n",
       " 'V54',\n",
       " 'V55',\n",
       " 'V56',\n",
       " 'V57',\n",
       " 'V58',\n",
       " 'V59',\n",
       " 'V60',\n",
       " 'Class']"
      ]
     },
     "execution_count": 4,
     "metadata": {},
     "output_type": "execute_result"
    },
    {
     "name": "stderr",
     "output_type": "stream",
     "text": [
      "Exception in callback BaseSelectorEventLoop._read_from_self()\n",
      "handle: <Handle BaseSelectorEventLoop._read_from_self()>\n",
      "Traceback (most recent call last):\n",
      "  File \"C:\\Users\\Admin\\anaconda3\\lib\\asyncio\\events.py\", line 81, in _run\n",
      "    self._context.run(self._callback, *self._args)\n",
      "  File \"C:\\Users\\Admin\\anaconda3\\lib\\asyncio\\selector_events.py\", line 120, in _read_from_self\n",
      "    data = self._ssock.recv(4096)\n",
      "ConnectionResetError: [WinError 10054] An existing connection was forcibly closed by the remote host\n",
      "Exception in callback BaseSelectorEventLoop._read_from_self()\n",
      "handle: <Handle BaseSelectorEventLoop._read_from_self()>\n",
      "Traceback (most recent call last):\n",
      "  File \"C:\\Users\\Admin\\anaconda3\\lib\\asyncio\\events.py\", line 81, in _run\n",
      "    self._context.run(self._callback, *self._args)\n",
      "  File \"C:\\Users\\Admin\\anaconda3\\lib\\asyncio\\selector_events.py\", line 120, in _read_from_self\n",
      "    data = self._ssock.recv(4096)\n",
      "ConnectionResetError: [WinError 10054] An existing connection was forcibly closed by the remote host\n",
      "Exception in callback BaseSelectorEventLoop._read_from_self()\n",
      "handle: <Handle BaseSelectorEventLoop._read_from_self()>\n",
      "Traceback (most recent call last):\n",
      "  File \"C:\\Users\\Admin\\anaconda3\\lib\\asyncio\\events.py\", line 81, in _run\n",
      "    self._context.run(self._callback, *self._args)\n",
      "  File \"C:\\Users\\Admin\\anaconda3\\lib\\asyncio\\selector_events.py\", line 120, in _read_from_self\n",
      "    data = self._ssock.recv(4096)\n",
      "ConnectionResetError: [WinError 10054] An existing connection was forcibly closed by the remote host\n",
      "Exception in callback BaseSelectorEventLoop._read_from_self()\n",
      "handle: <Handle BaseSelectorEventLoop._read_from_self()>\n",
      "Traceback (most recent call last):\n",
      "  File \"C:\\Users\\Admin\\anaconda3\\lib\\asyncio\\events.py\", line 81, in _run\n",
      "    self._context.run(self._callback, *self._args)\n",
      "  File \"C:\\Users\\Admin\\anaconda3\\lib\\asyncio\\selector_events.py\", line 120, in _read_from_self\n",
      "    data = self._ssock.recv(4096)\n",
      "ConnectionResetError: [WinError 10054] An existing connection was forcibly closed by the remote host\n",
      "Exception in callback BaseSelectorEventLoop._read_from_self()\n",
      "handle: <Handle BaseSelectorEventLoop._read_from_self()>\n",
      "Traceback (most recent call last):\n",
      "  File \"C:\\Users\\Admin\\anaconda3\\lib\\asyncio\\events.py\", line 81, in _run\n",
      "    self._context.run(self._callback, *self._args)\n",
      "  File \"C:\\Users\\Admin\\anaconda3\\lib\\asyncio\\selector_events.py\", line 120, in _read_from_self\n",
      "    data = self._ssock.recv(4096)\n",
      "ConnectionResetError: [WinError 10054] An existing connection was forcibly closed by the remote host\n",
      "Exception in callback BaseSelectorEventLoop._read_from_self()\n",
      "handle: <Handle BaseSelectorEventLoop._read_from_self()>\n",
      "Traceback (most recent call last):\n",
      "  File \"C:\\Users\\Admin\\anaconda3\\lib\\asyncio\\events.py\", line 81, in _run\n",
      "    self._context.run(self._callback, *self._args)\n",
      "  File \"C:\\Users\\Admin\\anaconda3\\lib\\asyncio\\selector_events.py\", line 120, in _read_from_self\n",
      "    data = self._ssock.recv(4096)\n",
      "ConnectionResetError: [WinError 10054] An existing connection was forcibly closed by the remote host\n",
      "Exception in callback BaseSelectorEventLoop._read_from_self()\n",
      "handle: <Handle BaseSelectorEventLoop._read_from_self()>\n",
      "Traceback (most recent call last):\n",
      "  File \"C:\\Users\\Admin\\anaconda3\\lib\\asyncio\\events.py\", line 81, in _run\n",
      "    self._context.run(self._callback, *self._args)\n",
      "  File \"C:\\Users\\Admin\\anaconda3\\lib\\asyncio\\selector_events.py\", line 120, in _read_from_self\n",
      "    data = self._ssock.recv(4096)\n",
      "ConnectionResetError: [WinError 10054] An existing connection was forcibly closed by the remote host\n",
      "Exception in callback BaseSelectorEventLoop._read_from_self()\n",
      "handle: <Handle BaseSelectorEventLoop._read_from_self()>\n",
      "Traceback (most recent call last):\n",
      "  File \"C:\\Users\\Admin\\anaconda3\\lib\\asyncio\\events.py\", line 81, in _run\n",
      "    self._context.run(self._callback, *self._args)\n",
      "  File \"C:\\Users\\Admin\\anaconda3\\lib\\asyncio\\selector_events.py\", line 120, in _read_from_self\n",
      "    data = self._ssock.recv(4096)\n",
      "ConnectionResetError: [WinError 10054] An existing connection was forcibly closed by the remote host\n",
      "Exception in callback BaseSelectorEventLoop._read_from_self()\n",
      "handle: <Handle BaseSelectorEventLoop._read_from_self()>\n",
      "Traceback (most recent call last):\n",
      "  File \"C:\\Users\\Admin\\anaconda3\\lib\\asyncio\\events.py\", line 81, in _run\n",
      "    self._context.run(self._callback, *self._args)\n",
      "  File \"C:\\Users\\Admin\\anaconda3\\lib\\asyncio\\selector_events.py\", line 120, in _read_from_self\n",
      "    data = self._ssock.recv(4096)\n",
      "ConnectionResetError: [WinError 10054] An existing connection was forcibly closed by the remote host\n",
      "Exception in callback BaseSelectorEventLoop._read_from_self()\n",
      "handle: <Handle BaseSelectorEventLoop._read_from_self()>\n",
      "Traceback (most recent call last):\n",
      "  File \"C:\\Users\\Admin\\anaconda3\\lib\\asyncio\\events.py\", line 81, in _run\n",
      "    self._context.run(self._callback, *self._args)\n",
      "  File \"C:\\Users\\Admin\\anaconda3\\lib\\asyncio\\selector_events.py\", line 120, in _read_from_self\n",
      "    data = self._ssock.recv(4096)\n",
      "ConnectionResetError: [WinError 10054] An existing connection was forcibly closed by the remote host\n",
      "Exception in callback BaseSelectorEventLoop._read_from_self()\n",
      "handle: <Handle BaseSelectorEventLoop._read_from_self()>\n",
      "Traceback (most recent call last):\n",
      "  File \"C:\\Users\\Admin\\anaconda3\\lib\\asyncio\\events.py\", line 81, in _run\n",
      "    self._context.run(self._callback, *self._args)\n",
      "  File \"C:\\Users\\Admin\\anaconda3\\lib\\asyncio\\selector_events.py\", line 120, in _read_from_self\n",
      "    data = self._ssock.recv(4096)\n",
      "ConnectionResetError: [WinError 10054] An existing connection was forcibly closed by the remote host\n",
      "Exception in callback BaseSelectorEventLoop._read_from_self()\n",
      "handle: <Handle BaseSelectorEventLoop._read_from_self()>\n",
      "Traceback (most recent call last):\n",
      "  File \"C:\\Users\\Admin\\anaconda3\\lib\\asyncio\\events.py\", line 81, in _run\n",
      "    self._context.run(self._callback, *self._args)\n",
      "  File \"C:\\Users\\Admin\\anaconda3\\lib\\asyncio\\selector_events.py\", line 120, in _read_from_self\n",
      "    data = self._ssock.recv(4096)\n",
      "ConnectionResetError: [WinError 10054] An existing connection was forcibly closed by the remote host\n",
      "Exception in callback BaseSelectorEventLoop._read_from_self()\n",
      "handle: <Handle BaseSelectorEventLoop._read_from_self()>\n",
      "Traceback (most recent call last):\n",
      "  File \"C:\\Users\\Admin\\anaconda3\\lib\\asyncio\\events.py\", line 81, in _run\n",
      "    self._context.run(self._callback, *self._args)\n",
      "  File \"C:\\Users\\Admin\\anaconda3\\lib\\asyncio\\selector_events.py\", line 120, in _read_from_self\n",
      "    data = self._ssock.recv(4096)\n",
      "ConnectionResetError: [WinError 10054] An existing connection was forcibly closed by the remote host\n",
      "Exception in callback BaseSelectorEventLoop._read_from_self()\n",
      "handle: <Handle BaseSelectorEventLoop._read_from_self()>\n",
      "Traceback (most recent call last):\n",
      "  File \"C:\\Users\\Admin\\anaconda3\\lib\\asyncio\\events.py\", line 81, in _run\n",
      "    self._context.run(self._callback, *self._args)\n",
      "  File \"C:\\Users\\Admin\\anaconda3\\lib\\asyncio\\selector_events.py\", line 120, in _read_from_self\n",
      "    data = self._ssock.recv(4096)\n",
      "ConnectionResetError: [WinError 10054] An existing connection was forcibly closed by the remote host\n",
      "Exception in callback BaseSelectorEventLoop._read_from_self()\n",
      "handle: <Handle BaseSelectorEventLoop._read_from_self()>\n",
      "Traceback (most recent call last):\n",
      "  File \"C:\\Users\\Admin\\anaconda3\\lib\\asyncio\\events.py\", line 81, in _run\n",
      "    self._context.run(self._callback, *self._args)\n",
      "  File \"C:\\Users\\Admin\\anaconda3\\lib\\asyncio\\selector_events.py\", line 120, in _read_from_self\n",
      "    data = self._ssock.recv(4096)\n",
      "ConnectionResetError: [WinError 10054] An existing connection was forcibly closed by the remote host\n",
      "Exception in callback BaseSelectorEventLoop._read_from_self()\n",
      "handle: <Handle BaseSelectorEventLoop._read_from_self()>\n",
      "Traceback (most recent call last):\n",
      "  File \"C:\\Users\\Admin\\anaconda3\\lib\\asyncio\\events.py\", line 81, in _run\n",
      "    self._context.run(self._callback, *self._args)\n",
      "  File \"C:\\Users\\Admin\\anaconda3\\lib\\asyncio\\selector_events.py\", line 120, in _read_from_self\n",
      "    data = self._ssock.recv(4096)\n",
      "ConnectionResetError: [WinError 10054] An existing connection was forcibly closed by the remote host\n",
      "Exception in callback BaseSelectorEventLoop._read_from_self()\n",
      "handle: <Handle BaseSelectorEventLoop._read_from_self()>\n",
      "Traceback (most recent call last):\n",
      "  File \"C:\\Users\\Admin\\anaconda3\\lib\\asyncio\\events.py\", line 81, in _run\n",
      "    self._context.run(self._callback, *self._args)\n",
      "  File \"C:\\Users\\Admin\\anaconda3\\lib\\asyncio\\selector_events.py\", line 120, in _read_from_self\n",
      "    data = self._ssock.recv(4096)\n",
      "ConnectionResetError: [WinError 10054] An existing connection was forcibly closed by the remote host\n"
     ]
    },
    {
     "name": "stderr",
     "output_type": "stream",
     "text": [
      "Exception in callback BaseSelectorEventLoop._read_from_self()\n",
      "handle: <Handle BaseSelectorEventLoop._read_from_self()>\n",
      "Traceback (most recent call last):\n",
      "  File \"C:\\Users\\Admin\\anaconda3\\lib\\asyncio\\events.py\", line 81, in _run\n",
      "    self._context.run(self._callback, *self._args)\n",
      "  File \"C:\\Users\\Admin\\anaconda3\\lib\\asyncio\\selector_events.py\", line 120, in _read_from_self\n",
      "    data = self._ssock.recv(4096)\n",
      "ConnectionResetError: [WinError 10054] An existing connection was forcibly closed by the remote host\n",
      "Exception in callback BaseSelectorEventLoop._read_from_self()\n",
      "handle: <Handle BaseSelectorEventLoop._read_from_self()>\n",
      "Traceback (most recent call last):\n",
      "  File \"C:\\Users\\Admin\\anaconda3\\lib\\asyncio\\events.py\", line 81, in _run\n",
      "    self._context.run(self._callback, *self._args)\n",
      "  File \"C:\\Users\\Admin\\anaconda3\\lib\\asyncio\\selector_events.py\", line 120, in _read_from_self\n",
      "    data = self._ssock.recv(4096)\n",
      "ConnectionResetError: [WinError 10054] An existing connection was forcibly closed by the remote host\n",
      "Exception in callback BaseSelectorEventLoop._read_from_self()\n",
      "handle: <Handle BaseSelectorEventLoop._read_from_self()>\n",
      "Traceback (most recent call last):\n",
      "  File \"C:\\Users\\Admin\\anaconda3\\lib\\asyncio\\events.py\", line 81, in _run\n",
      "    self._context.run(self._callback, *self._args)\n",
      "  File \"C:\\Users\\Admin\\anaconda3\\lib\\asyncio\\selector_events.py\", line 120, in _read_from_self\n",
      "    data = self._ssock.recv(4096)\n",
      "ConnectionResetError: [WinError 10054] An existing connection was forcibly closed by the remote host\n",
      "Exception in callback BaseSelectorEventLoop._read_from_self()\n",
      "handle: <Handle BaseSelectorEventLoop._read_from_self()>\n",
      "Traceback (most recent call last):\n",
      "  File \"C:\\Users\\Admin\\anaconda3\\lib\\asyncio\\events.py\", line 81, in _run\n",
      "    self._context.run(self._callback, *self._args)\n",
      "  File \"C:\\Users\\Admin\\anaconda3\\lib\\asyncio\\selector_events.py\", line 120, in _read_from_self\n",
      "    data = self._ssock.recv(4096)\n",
      "ConnectionResetError: [WinError 10054] An existing connection was forcibly closed by the remote host\n",
      "Exception in callback BaseSelectorEventLoop._read_from_self()\n",
      "handle: <Handle BaseSelectorEventLoop._read_from_self()>\n",
      "Traceback (most recent call last):\n",
      "  File \"C:\\Users\\Admin\\anaconda3\\lib\\asyncio\\events.py\", line 81, in _run\n",
      "    self._context.run(self._callback, *self._args)\n",
      "  File \"C:\\Users\\Admin\\anaconda3\\lib\\asyncio\\selector_events.py\", line 120, in _read_from_self\n",
      "    data = self._ssock.recv(4096)\n",
      "ConnectionResetError: [WinError 10054] An existing connection was forcibly closed by the remote host\n",
      "Exception in callback BaseSelectorEventLoop._read_from_self()\n",
      "handle: <Handle BaseSelectorEventLoop._read_from_self()>\n",
      "Traceback (most recent call last):\n",
      "  File \"C:\\Users\\Admin\\anaconda3\\lib\\asyncio\\events.py\", line 81, in _run\n",
      "    self._context.run(self._callback, *self._args)\n",
      "  File \"C:\\Users\\Admin\\anaconda3\\lib\\asyncio\\selector_events.py\", line 120, in _read_from_self\n",
      "    data = self._ssock.recv(4096)\n",
      "ConnectionResetError: [WinError 10054] An existing connection was forcibly closed by the remote host\n",
      "Exception in callback BaseSelectorEventLoop._read_from_self()\n",
      "handle: <Handle BaseSelectorEventLoop._read_from_self()>\n",
      "Traceback (most recent call last):\n",
      "  File \"C:\\Users\\Admin\\anaconda3\\lib\\asyncio\\events.py\", line 81, in _run\n",
      "    self._context.run(self._callback, *self._args)\n",
      "  File \"C:\\Users\\Admin\\anaconda3\\lib\\asyncio\\selector_events.py\", line 120, in _read_from_self\n",
      "    data = self._ssock.recv(4096)\n",
      "ConnectionResetError: [WinError 10054] An existing connection was forcibly closed by the remote host\n",
      "Exception in callback BaseSelectorEventLoop._read_from_self()\n",
      "handle: <Handle BaseSelectorEventLoop._read_from_self()>\n",
      "Traceback (most recent call last):\n",
      "  File \"C:\\Users\\Admin\\anaconda3\\lib\\asyncio\\events.py\", line 81, in _run\n",
      "    self._context.run(self._callback, *self._args)\n",
      "  File \"C:\\Users\\Admin\\anaconda3\\lib\\asyncio\\selector_events.py\", line 120, in _read_from_self\n",
      "    data = self._ssock.recv(4096)\n",
      "ConnectionResetError: [WinError 10054] An existing connection was forcibly closed by the remote host\n",
      "Exception in callback BaseSelectorEventLoop._read_from_self()\n",
      "handle: <Handle BaseSelectorEventLoop._read_from_self()>\n",
      "Traceback (most recent call last):\n",
      "  File \"C:\\Users\\Admin\\anaconda3\\lib\\asyncio\\events.py\", line 81, in _run\n",
      "    self._context.run(self._callback, *self._args)\n",
      "  File \"C:\\Users\\Admin\\anaconda3\\lib\\asyncio\\selector_events.py\", line 120, in _read_from_self\n",
      "    data = self._ssock.recv(4096)\n",
      "ConnectionResetError: [WinError 10054] An existing connection was forcibly closed by the remote host\n",
      "Exception in callback BaseSelectorEventLoop._read_from_self()\n",
      "handle: <Handle BaseSelectorEventLoop._read_from_self()>\n",
      "Traceback (most recent call last):\n",
      "  File \"C:\\Users\\Admin\\anaconda3\\lib\\asyncio\\events.py\", line 81, in _run\n",
      "    self._context.run(self._callback, *self._args)\n",
      "  File \"C:\\Users\\Admin\\anaconda3\\lib\\asyncio\\selector_events.py\", line 120, in _read_from_self\n",
      "    data = self._ssock.recv(4096)\n",
      "ConnectionResetError: [WinError 10054] An existing connection was forcibly closed by the remote host\n",
      "Exception in callback BaseSelectorEventLoop._read_from_self()\n",
      "handle: <Handle BaseSelectorEventLoop._read_from_self()>\n",
      "Traceback (most recent call last):\n",
      "  File \"C:\\Users\\Admin\\anaconda3\\lib\\asyncio\\events.py\", line 81, in _run\n",
      "    self._context.run(self._callback, *self._args)\n",
      "  File \"C:\\Users\\Admin\\anaconda3\\lib\\asyncio\\selector_events.py\", line 120, in _read_from_self\n",
      "    data = self._ssock.recv(4096)\n",
      "ConnectionResetError: [WinError 10054] An existing connection was forcibly closed by the remote host\n",
      "Exception in callback BaseSelectorEventLoop._read_from_self()\n",
      "handle: <Handle BaseSelectorEventLoop._read_from_self()>\n",
      "Traceback (most recent call last):\n",
      "  File \"C:\\Users\\Admin\\anaconda3\\lib\\asyncio\\events.py\", line 81, in _run\n",
      "    self._context.run(self._callback, *self._args)\n",
      "  File \"C:\\Users\\Admin\\anaconda3\\lib\\asyncio\\selector_events.py\", line 120, in _read_from_self\n",
      "    data = self._ssock.recv(4096)\n",
      "ConnectionResetError: [WinError 10054] An existing connection was forcibly closed by the remote host\n",
      "Exception in callback BaseSelectorEventLoop._read_from_self()\n",
      "handle: <Handle BaseSelectorEventLoop._read_from_self()>\n",
      "Traceback (most recent call last):\n",
      "  File \"C:\\Users\\Admin\\anaconda3\\lib\\asyncio\\events.py\", line 81, in _run\n",
      "    self._context.run(self._callback, *self._args)\n",
      "  File \"C:\\Users\\Admin\\anaconda3\\lib\\asyncio\\selector_events.py\", line 120, in _read_from_self\n",
      "    data = self._ssock.recv(4096)\n",
      "ConnectionResetError: [WinError 10054] An existing connection was forcibly closed by the remote host\n",
      "Exception in callback BaseSelectorEventLoop._read_from_self()\n",
      "handle: <Handle BaseSelectorEventLoop._read_from_self()>\n",
      "Traceback (most recent call last):\n",
      "  File \"C:\\Users\\Admin\\anaconda3\\lib\\asyncio\\events.py\", line 81, in _run\n",
      "    self._context.run(self._callback, *self._args)\n",
      "  File \"C:\\Users\\Admin\\anaconda3\\lib\\asyncio\\selector_events.py\", line 120, in _read_from_self\n",
      "    data = self._ssock.recv(4096)\n",
      "ConnectionResetError: [WinError 10054] An existing connection was forcibly closed by the remote host\n",
      "Exception in callback BaseSelectorEventLoop._read_from_self()\n",
      "handle: <Handle BaseSelectorEventLoop._read_from_self()>\n",
      "Traceback (most recent call last):\n",
      "  File \"C:\\Users\\Admin\\anaconda3\\lib\\asyncio\\events.py\", line 81, in _run\n",
      "    self._context.run(self._callback, *self._args)\n",
      "  File \"C:\\Users\\Admin\\anaconda3\\lib\\asyncio\\selector_events.py\", line 120, in _read_from_self\n",
      "    data = self._ssock.recv(4096)\n",
      "ConnectionResetError: [WinError 10054] An existing connection was forcibly closed by the remote host\n",
      "Exception in callback BaseSelectorEventLoop._read_from_self()\n",
      "handle: <Handle BaseSelectorEventLoop._read_from_self()>\n",
      "Traceback (most recent call last):\n",
      "  File \"C:\\Users\\Admin\\anaconda3\\lib\\asyncio\\events.py\", line 81, in _run\n",
      "    self._context.run(self._callback, *self._args)\n",
      "  File \"C:\\Users\\Admin\\anaconda3\\lib\\asyncio\\selector_events.py\", line 120, in _read_from_self\n",
      "    data = self._ssock.recv(4096)\n",
      "ConnectionResetError: [WinError 10054] An existing connection was forcibly closed by the remote host\n",
      "Exception in callback BaseSelectorEventLoop._read_from_self()\n",
      "handle: <Handle BaseSelectorEventLoop._read_from_self()>\n",
      "Traceback (most recent call last):\n",
      "  File \"C:\\Users\\Admin\\anaconda3\\lib\\asyncio\\events.py\", line 81, in _run\n",
      "    self._context.run(self._callback, *self._args)\n",
      "  File \"C:\\Users\\Admin\\anaconda3\\lib\\asyncio\\selector_events.py\", line 120, in _read_from_self\n",
      "    data = self._ssock.recv(4096)\n",
      "ConnectionResetError: [WinError 10054] An existing connection was forcibly closed by the remote host\n"
     ]
    },
    {
     "name": "stderr",
     "output_type": "stream",
     "text": [
      "Exception in callback BaseSelectorEventLoop._read_from_self()\n",
      "handle: <Handle BaseSelectorEventLoop._read_from_self()>\n",
      "Traceback (most recent call last):\n",
      "  File \"C:\\Users\\Admin\\anaconda3\\lib\\asyncio\\events.py\", line 81, in _run\n",
      "    self._context.run(self._callback, *self._args)\n",
      "  File \"C:\\Users\\Admin\\anaconda3\\lib\\asyncio\\selector_events.py\", line 120, in _read_from_self\n",
      "    data = self._ssock.recv(4096)\n",
      "ConnectionResetError: [WinError 10054] An existing connection was forcibly closed by the remote host\n",
      "Exception in callback BaseSelectorEventLoop._read_from_self()\n",
      "handle: <Handle BaseSelectorEventLoop._read_from_self()>\n",
      "Traceback (most recent call last):\n",
      "  File \"C:\\Users\\Admin\\anaconda3\\lib\\asyncio\\events.py\", line 81, in _run\n",
      "    self._context.run(self._callback, *self._args)\n",
      "  File \"C:\\Users\\Admin\\anaconda3\\lib\\asyncio\\selector_events.py\", line 120, in _read_from_self\n",
      "    data = self._ssock.recv(4096)\n",
      "ConnectionResetError: [WinError 10054] An existing connection was forcibly closed by the remote host\n",
      "Exception in callback BaseSelectorEventLoop._read_from_self()\n",
      "handle: <Handle BaseSelectorEventLoop._read_from_self()>\n",
      "Traceback (most recent call last):\n",
      "  File \"C:\\Users\\Admin\\anaconda3\\lib\\asyncio\\events.py\", line 81, in _run\n",
      "    self._context.run(self._callback, *self._args)\n",
      "  File \"C:\\Users\\Admin\\anaconda3\\lib\\asyncio\\selector_events.py\", line 120, in _read_from_self\n",
      "    data = self._ssock.recv(4096)\n",
      "ConnectionResetError: [WinError 10054] An existing connection was forcibly closed by the remote host\n",
      "Exception in callback BaseSelectorEventLoop._read_from_self()\n",
      "handle: <Handle BaseSelectorEventLoop._read_from_self()>\n",
      "Traceback (most recent call last):\n",
      "  File \"C:\\Users\\Admin\\anaconda3\\lib\\asyncio\\events.py\", line 81, in _run\n",
      "    self._context.run(self._callback, *self._args)\n",
      "  File \"C:\\Users\\Admin\\anaconda3\\lib\\asyncio\\selector_events.py\", line 120, in _read_from_self\n",
      "    data = self._ssock.recv(4096)\n",
      "ConnectionResetError: [WinError 10054] An existing connection was forcibly closed by the remote host\n",
      "Exception in callback BaseSelectorEventLoop._read_from_self()\n",
      "handle: <Handle BaseSelectorEventLoop._read_from_self()>\n",
      "Traceback (most recent call last):\n",
      "  File \"C:\\Users\\Admin\\anaconda3\\lib\\asyncio\\events.py\", line 81, in _run\n",
      "    self._context.run(self._callback, *self._args)\n",
      "  File \"C:\\Users\\Admin\\anaconda3\\lib\\asyncio\\selector_events.py\", line 120, in _read_from_self\n",
      "    data = self._ssock.recv(4096)\n",
      "ConnectionResetError: [WinError 10054] An existing connection was forcibly closed by the remote host\n",
      "Exception in callback BaseSelectorEventLoop._read_from_self()\n",
      "handle: <Handle BaseSelectorEventLoop._read_from_self()>\n",
      "Traceback (most recent call last):\n",
      "  File \"C:\\Users\\Admin\\anaconda3\\lib\\asyncio\\events.py\", line 81, in _run\n",
      "    self._context.run(self._callback, *self._args)\n",
      "  File \"C:\\Users\\Admin\\anaconda3\\lib\\asyncio\\selector_events.py\", line 120, in _read_from_self\n",
      "    data = self._ssock.recv(4096)\n",
      "ConnectionResetError: [WinError 10054] An existing connection was forcibly closed by the remote host\n",
      "Exception in callback BaseSelectorEventLoop._read_from_self()\n",
      "handle: <Handle BaseSelectorEventLoop._read_from_self()>\n",
      "Traceback (most recent call last):\n",
      "  File \"C:\\Users\\Admin\\anaconda3\\lib\\asyncio\\events.py\", line 81, in _run\n",
      "    self._context.run(self._callback, *self._args)\n",
      "  File \"C:\\Users\\Admin\\anaconda3\\lib\\asyncio\\selector_events.py\", line 120, in _read_from_self\n",
      "    data = self._ssock.recv(4096)\n",
      "ConnectionResetError: [WinError 10054] An existing connection was forcibly closed by the remote host\n",
      "Exception in callback BaseSelectorEventLoop._read_from_self()\n",
      "handle: <Handle BaseSelectorEventLoop._read_from_self()>\n",
      "Traceback (most recent call last):\n",
      "  File \"C:\\Users\\Admin\\anaconda3\\lib\\asyncio\\events.py\", line 81, in _run\n",
      "    self._context.run(self._callback, *self._args)\n",
      "  File \"C:\\Users\\Admin\\anaconda3\\lib\\asyncio\\selector_events.py\", line 120, in _read_from_self\n",
      "    data = self._ssock.recv(4096)\n",
      "ConnectionResetError: [WinError 10054] An existing connection was forcibly closed by the remote host\n",
      "Exception in callback BaseSelectorEventLoop._read_from_self()\n",
      "handle: <Handle BaseSelectorEventLoop._read_from_self()>\n",
      "Traceback (most recent call last):\n",
      "  File \"C:\\Users\\Admin\\anaconda3\\lib\\asyncio\\events.py\", line 81, in _run\n",
      "    self._context.run(self._callback, *self._args)\n",
      "  File \"C:\\Users\\Admin\\anaconda3\\lib\\asyncio\\selector_events.py\", line 120, in _read_from_self\n",
      "    data = self._ssock.recv(4096)\n",
      "ConnectionResetError: [WinError 10054] An existing connection was forcibly closed by the remote host\n",
      "Exception in callback BaseSelectorEventLoop._read_from_self()\n",
      "handle: <Handle BaseSelectorEventLoop._read_from_self()>\n",
      "Traceback (most recent call last):\n",
      "  File \"C:\\Users\\Admin\\anaconda3\\lib\\asyncio\\events.py\", line 81, in _run\n",
      "    self._context.run(self._callback, *self._args)\n",
      "  File \"C:\\Users\\Admin\\anaconda3\\lib\\asyncio\\selector_events.py\", line 120, in _read_from_self\n",
      "    data = self._ssock.recv(4096)\n",
      "ConnectionResetError: [WinError 10054] An existing connection was forcibly closed by the remote host\n",
      "Exception in callback BaseSelectorEventLoop._read_from_self()\n",
      "handle: <Handle BaseSelectorEventLoop._read_from_self()>\n",
      "Traceback (most recent call last):\n",
      "  File \"C:\\Users\\Admin\\anaconda3\\lib\\asyncio\\events.py\", line 81, in _run\n",
      "    self._context.run(self._callback, *self._args)\n",
      "  File \"C:\\Users\\Admin\\anaconda3\\lib\\asyncio\\selector_events.py\", line 120, in _read_from_self\n",
      "    data = self._ssock.recv(4096)\n",
      "ConnectionResetError: [WinError 10054] An existing connection was forcibly closed by the remote host\n",
      "Exception in callback BaseSelectorEventLoop._read_from_self()\n",
      "handle: <Handle BaseSelectorEventLoop._read_from_self()>\n",
      "Traceback (most recent call last):\n",
      "  File \"C:\\Users\\Admin\\anaconda3\\lib\\asyncio\\events.py\", line 81, in _run\n",
      "    self._context.run(self._callback, *self._args)\n",
      "  File \"C:\\Users\\Admin\\anaconda3\\lib\\asyncio\\selector_events.py\", line 120, in _read_from_self\n",
      "    data = self._ssock.recv(4096)\n",
      "ConnectionResetError: [WinError 10054] An existing connection was forcibly closed by the remote host\n",
      "Exception in callback BaseSelectorEventLoop._read_from_self()\n",
      "handle: <Handle BaseSelectorEventLoop._read_from_self()>\n",
      "Traceback (most recent call last):\n",
      "  File \"C:\\Users\\Admin\\anaconda3\\lib\\asyncio\\events.py\", line 81, in _run\n",
      "    self._context.run(self._callback, *self._args)\n",
      "  File \"C:\\Users\\Admin\\anaconda3\\lib\\asyncio\\selector_events.py\", line 120, in _read_from_self\n",
      "    data = self._ssock.recv(4096)\n",
      "ConnectionResetError: [WinError 10054] An existing connection was forcibly closed by the remote host\n",
      "Exception in callback BaseSelectorEventLoop._read_from_self()\n",
      "handle: <Handle BaseSelectorEventLoop._read_from_self()>\n",
      "Traceback (most recent call last):\n",
      "  File \"C:\\Users\\Admin\\anaconda3\\lib\\asyncio\\events.py\", line 81, in _run\n",
      "    self._context.run(self._callback, *self._args)\n",
      "  File \"C:\\Users\\Admin\\anaconda3\\lib\\asyncio\\selector_events.py\", line 120, in _read_from_self\n",
      "    data = self._ssock.recv(4096)\n",
      "ConnectionResetError: [WinError 10054] An existing connection was forcibly closed by the remote host\n",
      "Exception in callback BaseSelectorEventLoop._read_from_self()\n",
      "handle: <Handle BaseSelectorEventLoop._read_from_self()>\n",
      "Traceback (most recent call last):\n",
      "  File \"C:\\Users\\Admin\\anaconda3\\lib\\asyncio\\events.py\", line 81, in _run\n",
      "    self._context.run(self._callback, *self._args)\n",
      "  File \"C:\\Users\\Admin\\anaconda3\\lib\\asyncio\\selector_events.py\", line 120, in _read_from_self\n",
      "    data = self._ssock.recv(4096)\n",
      "ConnectionResetError: [WinError 10054] An existing connection was forcibly closed by the remote host\n",
      "Exception in callback BaseSelectorEventLoop._read_from_self()\n",
      "handle: <Handle BaseSelectorEventLoop._read_from_self()>\n",
      "Traceback (most recent call last):\n",
      "  File \"C:\\Users\\Admin\\anaconda3\\lib\\asyncio\\events.py\", line 81, in _run\n",
      "    self._context.run(self._callback, *self._args)\n",
      "  File \"C:\\Users\\Admin\\anaconda3\\lib\\asyncio\\selector_events.py\", line 120, in _read_from_self\n",
      "    data = self._ssock.recv(4096)\n",
      "ConnectionResetError: [WinError 10054] An existing connection was forcibly closed by the remote host\n",
      "Exception in callback BaseSelectorEventLoop._read_from_self()\n",
      "handle: <Handle BaseSelectorEventLoop._read_from_self()>\n",
      "Traceback (most recent call last):\n",
      "  File \"C:\\Users\\Admin\\anaconda3\\lib\\asyncio\\events.py\", line 81, in _run\n",
      "    self._context.run(self._callback, *self._args)\n",
      "  File \"C:\\Users\\Admin\\anaconda3\\lib\\asyncio\\selector_events.py\", line 120, in _read_from_self\n",
      "    data = self._ssock.recv(4096)\n",
      "ConnectionResetError: [WinError 10054] An existing connection was forcibly closed by the remote host\n"
     ]
    },
    {
     "name": "stderr",
     "output_type": "stream",
     "text": [
      "Exception in callback BaseSelectorEventLoop._read_from_self()\n",
      "handle: <Handle BaseSelectorEventLoop._read_from_self()>\n",
      "Traceback (most recent call last):\n",
      "  File \"C:\\Users\\Admin\\anaconda3\\lib\\asyncio\\events.py\", line 81, in _run\n",
      "    self._context.run(self._callback, *self._args)\n",
      "  File \"C:\\Users\\Admin\\anaconda3\\lib\\asyncio\\selector_events.py\", line 120, in _read_from_self\n",
      "    data = self._ssock.recv(4096)\n",
      "ConnectionResetError: [WinError 10054] An existing connection was forcibly closed by the remote host\n",
      "Exception in callback BaseSelectorEventLoop._read_from_self()\n",
      "handle: <Handle BaseSelectorEventLoop._read_from_self()>\n",
      "Traceback (most recent call last):\n",
      "  File \"C:\\Users\\Admin\\anaconda3\\lib\\asyncio\\events.py\", line 81, in _run\n",
      "    self._context.run(self._callback, *self._args)\n",
      "  File \"C:\\Users\\Admin\\anaconda3\\lib\\asyncio\\selector_events.py\", line 120, in _read_from_self\n",
      "    data = self._ssock.recv(4096)\n",
      "ConnectionResetError: [WinError 10054] An existing connection was forcibly closed by the remote host\n",
      "Exception in callback BaseSelectorEventLoop._read_from_self()\n",
      "handle: <Handle BaseSelectorEventLoop._read_from_self()>\n",
      "Traceback (most recent call last):\n",
      "  File \"C:\\Users\\Admin\\anaconda3\\lib\\asyncio\\events.py\", line 81, in _run\n",
      "    self._context.run(self._callback, *self._args)\n",
      "  File \"C:\\Users\\Admin\\anaconda3\\lib\\asyncio\\selector_events.py\", line 120, in _read_from_self\n",
      "    data = self._ssock.recv(4096)\n",
      "ConnectionResetError: [WinError 10054] An existing connection was forcibly closed by the remote host\n",
      "Exception in callback BaseSelectorEventLoop._read_from_self()\n",
      "handle: <Handle BaseSelectorEventLoop._read_from_self()>\n",
      "Traceback (most recent call last):\n",
      "  File \"C:\\Users\\Admin\\anaconda3\\lib\\asyncio\\events.py\", line 81, in _run\n",
      "    self._context.run(self._callback, *self._args)\n",
      "  File \"C:\\Users\\Admin\\anaconda3\\lib\\asyncio\\selector_events.py\", line 120, in _read_from_self\n",
      "    data = self._ssock.recv(4096)\n",
      "ConnectionResetError: [WinError 10054] An existing connection was forcibly closed by the remote host\n",
      "Exception in callback BaseSelectorEventLoop._read_from_self()\n",
      "handle: <Handle BaseSelectorEventLoop._read_from_self()>\n",
      "Traceback (most recent call last):\n",
      "  File \"C:\\Users\\Admin\\anaconda3\\lib\\asyncio\\events.py\", line 81, in _run\n",
      "    self._context.run(self._callback, *self._args)\n",
      "  File \"C:\\Users\\Admin\\anaconda3\\lib\\asyncio\\selector_events.py\", line 120, in _read_from_self\n",
      "    data = self._ssock.recv(4096)\n",
      "ConnectionResetError: [WinError 10054] An existing connection was forcibly closed by the remote host\n",
      "Exception in callback BaseSelectorEventLoop._read_from_self()\n",
      "handle: <Handle BaseSelectorEventLoop._read_from_self()>\n",
      "Traceback (most recent call last):\n",
      "  File \"C:\\Users\\Admin\\anaconda3\\lib\\asyncio\\events.py\", line 81, in _run\n",
      "    self._context.run(self._callback, *self._args)\n",
      "  File \"C:\\Users\\Admin\\anaconda3\\lib\\asyncio\\selector_events.py\", line 120, in _read_from_self\n",
      "    data = self._ssock.recv(4096)\n",
      "ConnectionResetError: [WinError 10054] An existing connection was forcibly closed by the remote host\n",
      "Exception in callback BaseSelectorEventLoop._read_from_self()\n",
      "handle: <Handle BaseSelectorEventLoop._read_from_self()>\n",
      "Traceback (most recent call last):\n",
      "  File \"C:\\Users\\Admin\\anaconda3\\lib\\asyncio\\events.py\", line 81, in _run\n",
      "    self._context.run(self._callback, *self._args)\n",
      "  File \"C:\\Users\\Admin\\anaconda3\\lib\\asyncio\\selector_events.py\", line 120, in _read_from_self\n",
      "    data = self._ssock.recv(4096)\n",
      "ConnectionResetError: [WinError 10054] An existing connection was forcibly closed by the remote host\n",
      "Exception in callback BaseSelectorEventLoop._read_from_self()\n",
      "handle: <Handle BaseSelectorEventLoop._read_from_self()>\n",
      "Traceback (most recent call last):\n",
      "  File \"C:\\Users\\Admin\\anaconda3\\lib\\asyncio\\events.py\", line 81, in _run\n",
      "    self._context.run(self._callback, *self._args)\n",
      "  File \"C:\\Users\\Admin\\anaconda3\\lib\\asyncio\\selector_events.py\", line 120, in _read_from_self\n",
      "    data = self._ssock.recv(4096)\n",
      "ConnectionResetError: [WinError 10054] An existing connection was forcibly closed by the remote host\n",
      "Exception in callback BaseSelectorEventLoop._read_from_self()\n",
      "handle: <Handle BaseSelectorEventLoop._read_from_self()>\n",
      "Traceback (most recent call last):\n",
      "  File \"C:\\Users\\Admin\\anaconda3\\lib\\asyncio\\events.py\", line 81, in _run\n",
      "    self._context.run(self._callback, *self._args)\n",
      "  File \"C:\\Users\\Admin\\anaconda3\\lib\\asyncio\\selector_events.py\", line 120, in _read_from_self\n",
      "    data = self._ssock.recv(4096)\n",
      "ConnectionResetError: [WinError 10054] An existing connection was forcibly closed by the remote host\n",
      "Exception in callback BaseSelectorEventLoop._read_from_self()\n",
      "handle: <Handle BaseSelectorEventLoop._read_from_self()>\n",
      "Traceback (most recent call last):\n",
      "  File \"C:\\Users\\Admin\\anaconda3\\lib\\asyncio\\events.py\", line 81, in _run\n",
      "    self._context.run(self._callback, *self._args)\n",
      "  File \"C:\\Users\\Admin\\anaconda3\\lib\\asyncio\\selector_events.py\", line 120, in _read_from_self\n",
      "    data = self._ssock.recv(4096)\n",
      "ConnectionResetError: [WinError 10054] An existing connection was forcibly closed by the remote host\n",
      "Exception in callback BaseSelectorEventLoop._read_from_self()\n",
      "handle: <Handle BaseSelectorEventLoop._read_from_self()>\n",
      "Traceback (most recent call last):\n",
      "  File \"C:\\Users\\Admin\\anaconda3\\lib\\asyncio\\events.py\", line 81, in _run\n",
      "    self._context.run(self._callback, *self._args)\n",
      "  File \"C:\\Users\\Admin\\anaconda3\\lib\\asyncio\\selector_events.py\", line 120, in _read_from_self\n",
      "    data = self._ssock.recv(4096)\n",
      "ConnectionResetError: [WinError 10054] An existing connection was forcibly closed by the remote host\n",
      "Exception in callback BaseSelectorEventLoop._read_from_self()\n",
      "handle: <Handle BaseSelectorEventLoop._read_from_self()>\n",
      "Traceback (most recent call last):\n",
      "  File \"C:\\Users\\Admin\\anaconda3\\lib\\asyncio\\events.py\", line 81, in _run\n",
      "    self._context.run(self._callback, *self._args)\n",
      "  File \"C:\\Users\\Admin\\anaconda3\\lib\\asyncio\\selector_events.py\", line 120, in _read_from_self\n",
      "    data = self._ssock.recv(4096)\n",
      "ConnectionResetError: [WinError 10054] An existing connection was forcibly closed by the remote host\n",
      "Exception in callback BaseSelectorEventLoop._read_from_self()\n",
      "handle: <Handle BaseSelectorEventLoop._read_from_self()>\n",
      "Traceback (most recent call last):\n",
      "  File \"C:\\Users\\Admin\\anaconda3\\lib\\asyncio\\events.py\", line 81, in _run\n",
      "    self._context.run(self._callback, *self._args)\n",
      "  File \"C:\\Users\\Admin\\anaconda3\\lib\\asyncio\\selector_events.py\", line 120, in _read_from_self\n",
      "    data = self._ssock.recv(4096)\n",
      "ConnectionResetError: [WinError 10054] An existing connection was forcibly closed by the remote host\n",
      "Exception in callback BaseSelectorEventLoop._read_from_self()\n",
      "handle: <Handle BaseSelectorEventLoop._read_from_self()>\n",
      "Traceback (most recent call last):\n",
      "  File \"C:\\Users\\Admin\\anaconda3\\lib\\asyncio\\events.py\", line 81, in _run\n",
      "    self._context.run(self._callback, *self._args)\n",
      "  File \"C:\\Users\\Admin\\anaconda3\\lib\\asyncio\\selector_events.py\", line 120, in _read_from_self\n",
      "    data = self._ssock.recv(4096)\n",
      "ConnectionResetError: [WinError 10054] An existing connection was forcibly closed by the remote host\n",
      "Exception in callback BaseSelectorEventLoop._read_from_self()\n",
      "handle: <Handle BaseSelectorEventLoop._read_from_self()>\n",
      "Traceback (most recent call last):\n",
      "  File \"C:\\Users\\Admin\\anaconda3\\lib\\asyncio\\events.py\", line 81, in _run\n",
      "    self._context.run(self._callback, *self._args)\n",
      "  File \"C:\\Users\\Admin\\anaconda3\\lib\\asyncio\\selector_events.py\", line 120, in _read_from_self\n",
      "    data = self._ssock.recv(4096)\n",
      "ConnectionResetError: [WinError 10054] An existing connection was forcibly closed by the remote host\n",
      "Exception in callback BaseSelectorEventLoop._read_from_self()\n",
      "handle: <Handle BaseSelectorEventLoop._read_from_self()>\n",
      "Traceback (most recent call last):\n",
      "  File \"C:\\Users\\Admin\\anaconda3\\lib\\asyncio\\events.py\", line 81, in _run\n",
      "    self._context.run(self._callback, *self._args)\n",
      "  File \"C:\\Users\\Admin\\anaconda3\\lib\\asyncio\\selector_events.py\", line 120, in _read_from_self\n",
      "    data = self._ssock.recv(4096)\n",
      "ConnectionResetError: [WinError 10054] An existing connection was forcibly closed by the remote host\n",
      "Exception in callback BaseSelectorEventLoop._read_from_self()\n",
      "handle: <Handle BaseSelectorEventLoop._read_from_self()>\n",
      "Traceback (most recent call last):\n",
      "  File \"C:\\Users\\Admin\\anaconda3\\lib\\asyncio\\events.py\", line 81, in _run\n",
      "    self._context.run(self._callback, *self._args)\n",
      "  File \"C:\\Users\\Admin\\anaconda3\\lib\\asyncio\\selector_events.py\", line 120, in _read_from_self\n",
      "    data = self._ssock.recv(4096)\n",
      "ConnectionResetError: [WinError 10054] An existing connection was forcibly closed by the remote host\n"
     ]
    },
    {
     "name": "stderr",
     "output_type": "stream",
     "text": [
      "Exception in callback BaseSelectorEventLoop._read_from_self()\n",
      "handle: <Handle BaseSelectorEventLoop._read_from_self()>\n",
      "Traceback (most recent call last):\n",
      "  File \"C:\\Users\\Admin\\anaconda3\\lib\\asyncio\\events.py\", line 81, in _run\n",
      "    self._context.run(self._callback, *self._args)\n",
      "  File \"C:\\Users\\Admin\\anaconda3\\lib\\asyncio\\selector_events.py\", line 120, in _read_from_self\n",
      "    data = self._ssock.recv(4096)\n",
      "ConnectionResetError: [WinError 10054] An existing connection was forcibly closed by the remote host\n",
      "Exception in callback BaseSelectorEventLoop._read_from_self()\n",
      "handle: <Handle BaseSelectorEventLoop._read_from_self()>\n",
      "Traceback (most recent call last):\n",
      "  File \"C:\\Users\\Admin\\anaconda3\\lib\\asyncio\\events.py\", line 81, in _run\n",
      "    self._context.run(self._callback, *self._args)\n",
      "  File \"C:\\Users\\Admin\\anaconda3\\lib\\asyncio\\selector_events.py\", line 120, in _read_from_self\n",
      "    data = self._ssock.recv(4096)\n",
      "ConnectionResetError: [WinError 10054] An existing connection was forcibly closed by the remote host\n",
      "Exception in callback BaseSelectorEventLoop._read_from_self()\n",
      "handle: <Handle BaseSelectorEventLoop._read_from_self()>\n",
      "Traceback (most recent call last):\n",
      "  File \"C:\\Users\\Admin\\anaconda3\\lib\\asyncio\\events.py\", line 81, in _run\n",
      "    self._context.run(self._callback, *self._args)\n",
      "  File \"C:\\Users\\Admin\\anaconda3\\lib\\asyncio\\selector_events.py\", line 120, in _read_from_self\n",
      "    data = self._ssock.recv(4096)\n",
      "ConnectionResetError: [WinError 10054] An existing connection was forcibly closed by the remote host\n",
      "Exception in callback BaseSelectorEventLoop._read_from_self()\n",
      "handle: <Handle BaseSelectorEventLoop._read_from_self()>\n",
      "Traceback (most recent call last):\n",
      "  File \"C:\\Users\\Admin\\anaconda3\\lib\\asyncio\\events.py\", line 81, in _run\n",
      "    self._context.run(self._callback, *self._args)\n",
      "  File \"C:\\Users\\Admin\\anaconda3\\lib\\asyncio\\selector_events.py\", line 120, in _read_from_self\n",
      "    data = self._ssock.recv(4096)\n",
      "ConnectionResetError: [WinError 10054] An existing connection was forcibly closed by the remote host\n",
      "Exception in callback BaseSelectorEventLoop._read_from_self()\n",
      "handle: <Handle BaseSelectorEventLoop._read_from_self()>\n",
      "Traceback (most recent call last):\n",
      "  File \"C:\\Users\\Admin\\anaconda3\\lib\\asyncio\\events.py\", line 81, in _run\n",
      "    self._context.run(self._callback, *self._args)\n",
      "  File \"C:\\Users\\Admin\\anaconda3\\lib\\asyncio\\selector_events.py\", line 120, in _read_from_self\n",
      "    data = self._ssock.recv(4096)\n",
      "ConnectionResetError: [WinError 10054] An existing connection was forcibly closed by the remote host\n",
      "Exception in callback BaseSelectorEventLoop._read_from_self()\n",
      "handle: <Handle BaseSelectorEventLoop._read_from_self()>\n",
      "Traceback (most recent call last):\n",
      "  File \"C:\\Users\\Admin\\anaconda3\\lib\\asyncio\\events.py\", line 81, in _run\n",
      "    self._context.run(self._callback, *self._args)\n",
      "  File \"C:\\Users\\Admin\\anaconda3\\lib\\asyncio\\selector_events.py\", line 120, in _read_from_self\n",
      "    data = self._ssock.recv(4096)\n",
      "ConnectionResetError: [WinError 10054] An existing connection was forcibly closed by the remote host\n",
      "Exception in callback BaseSelectorEventLoop._read_from_self()\n",
      "handle: <Handle BaseSelectorEventLoop._read_from_self()>\n",
      "Traceback (most recent call last):\n",
      "  File \"C:\\Users\\Admin\\anaconda3\\lib\\asyncio\\events.py\", line 81, in _run\n",
      "    self._context.run(self._callback, *self._args)\n",
      "  File \"C:\\Users\\Admin\\anaconda3\\lib\\asyncio\\selector_events.py\", line 120, in _read_from_self\n",
      "    data = self._ssock.recv(4096)\n",
      "ConnectionResetError: [WinError 10054] An existing connection was forcibly closed by the remote host\n",
      "Exception in callback BaseSelectorEventLoop._read_from_self()\n",
      "handle: <Handle BaseSelectorEventLoop._read_from_self()>\n",
      "Traceback (most recent call last):\n",
      "  File \"C:\\Users\\Admin\\anaconda3\\lib\\asyncio\\events.py\", line 81, in _run\n",
      "    self._context.run(self._callback, *self._args)\n",
      "  File \"C:\\Users\\Admin\\anaconda3\\lib\\asyncio\\selector_events.py\", line 120, in _read_from_self\n",
      "    data = self._ssock.recv(4096)\n",
      "ConnectionResetError: [WinError 10054] An existing connection was forcibly closed by the remote host\n",
      "Exception in callback BaseSelectorEventLoop._read_from_self()\n",
      "handle: <Handle BaseSelectorEventLoop._read_from_self()>\n",
      "Traceback (most recent call last):\n",
      "  File \"C:\\Users\\Admin\\anaconda3\\lib\\asyncio\\events.py\", line 81, in _run\n",
      "    self._context.run(self._callback, *self._args)\n",
      "  File \"C:\\Users\\Admin\\anaconda3\\lib\\asyncio\\selector_events.py\", line 120, in _read_from_self\n",
      "    data = self._ssock.recv(4096)\n",
      "ConnectionResetError: [WinError 10054] An existing connection was forcibly closed by the remote host\n",
      "Exception in callback BaseSelectorEventLoop._read_from_self()\n",
      "handle: <Handle BaseSelectorEventLoop._read_from_self()>\n",
      "Traceback (most recent call last):\n",
      "  File \"C:\\Users\\Admin\\anaconda3\\lib\\asyncio\\events.py\", line 81, in _run\n",
      "    self._context.run(self._callback, *self._args)\n",
      "  File \"C:\\Users\\Admin\\anaconda3\\lib\\asyncio\\selector_events.py\", line 120, in _read_from_self\n",
      "    data = self._ssock.recv(4096)\n",
      "ConnectionResetError: [WinError 10054] An existing connection was forcibly closed by the remote host\n",
      "Exception in callback BaseSelectorEventLoop._read_from_self()\n",
      "handle: <Handle BaseSelectorEventLoop._read_from_self()>\n",
      "Traceback (most recent call last):\n",
      "  File \"C:\\Users\\Admin\\anaconda3\\lib\\asyncio\\events.py\", line 81, in _run\n",
      "    self._context.run(self._callback, *self._args)\n",
      "  File \"C:\\Users\\Admin\\anaconda3\\lib\\asyncio\\selector_events.py\", line 120, in _read_from_self\n",
      "    data = self._ssock.recv(4096)\n",
      "ConnectionResetError: [WinError 10054] An existing connection was forcibly closed by the remote host\n",
      "Exception in callback BaseSelectorEventLoop._read_from_self()\n",
      "handle: <Handle BaseSelectorEventLoop._read_from_self()>\n",
      "Traceback (most recent call last):\n",
      "  File \"C:\\Users\\Admin\\anaconda3\\lib\\asyncio\\events.py\", line 81, in _run\n",
      "    self._context.run(self._callback, *self._args)\n",
      "  File \"C:\\Users\\Admin\\anaconda3\\lib\\asyncio\\selector_events.py\", line 120, in _read_from_self\n",
      "    data = self._ssock.recv(4096)\n",
      "ConnectionResetError: [WinError 10054] An existing connection was forcibly closed by the remote host\n",
      "Exception in callback BaseSelectorEventLoop._read_from_self()\n",
      "handle: <Handle BaseSelectorEventLoop._read_from_self()>\n",
      "Traceback (most recent call last):\n",
      "  File \"C:\\Users\\Admin\\anaconda3\\lib\\asyncio\\events.py\", line 81, in _run\n",
      "    self._context.run(self._callback, *self._args)\n",
      "  File \"C:\\Users\\Admin\\anaconda3\\lib\\asyncio\\selector_events.py\", line 120, in _read_from_self\n",
      "    data = self._ssock.recv(4096)\n",
      "ConnectionResetError: [WinError 10054] An existing connection was forcibly closed by the remote host\n",
      "Exception in callback BaseSelectorEventLoop._read_from_self()\n",
      "handle: <Handle BaseSelectorEventLoop._read_from_self()>\n",
      "Traceback (most recent call last):\n",
      "  File \"C:\\Users\\Admin\\anaconda3\\lib\\asyncio\\events.py\", line 81, in _run\n",
      "    self._context.run(self._callback, *self._args)\n",
      "  File \"C:\\Users\\Admin\\anaconda3\\lib\\asyncio\\selector_events.py\", line 120, in _read_from_self\n",
      "    data = self._ssock.recv(4096)\n",
      "ConnectionResetError: [WinError 10054] An existing connection was forcibly closed by the remote host\n",
      "Exception in callback BaseSelectorEventLoop._read_from_self()\n",
      "handle: <Handle BaseSelectorEventLoop._read_from_self()>\n",
      "Traceback (most recent call last):\n",
      "  File \"C:\\Users\\Admin\\anaconda3\\lib\\asyncio\\events.py\", line 81, in _run\n",
      "    self._context.run(self._callback, *self._args)\n",
      "  File \"C:\\Users\\Admin\\anaconda3\\lib\\asyncio\\selector_events.py\", line 120, in _read_from_self\n",
      "    data = self._ssock.recv(4096)\n",
      "ConnectionResetError: [WinError 10054] An existing connection was forcibly closed by the remote host\n",
      "Exception in callback BaseSelectorEventLoop._read_from_self()\n",
      "handle: <Handle BaseSelectorEventLoop._read_from_self()>\n",
      "Traceback (most recent call last):\n",
      "  File \"C:\\Users\\Admin\\anaconda3\\lib\\asyncio\\events.py\", line 81, in _run\n",
      "    self._context.run(self._callback, *self._args)\n",
      "  File \"C:\\Users\\Admin\\anaconda3\\lib\\asyncio\\selector_events.py\", line 120, in _read_from_self\n",
      "    data = self._ssock.recv(4096)\n",
      "ConnectionResetError: [WinError 10054] An existing connection was forcibly closed by the remote host\n",
      "Exception in callback BaseSelectorEventLoop._read_from_self()\n",
      "handle: <Handle BaseSelectorEventLoop._read_from_self()>\n",
      "Traceback (most recent call last):\n",
      "  File \"C:\\Users\\Admin\\anaconda3\\lib\\asyncio\\events.py\", line 81, in _run\n",
      "    self._context.run(self._callback, *self._args)\n",
      "  File \"C:\\Users\\Admin\\anaconda3\\lib\\asyncio\\selector_events.py\", line 120, in _read_from_self\n",
      "    data = self._ssock.recv(4096)\n",
      "ConnectionResetError: [WinError 10054] An existing connection was forcibly closed by the remote host\n"
     ]
    },
    {
     "name": "stderr",
     "output_type": "stream",
     "text": [
      "Exception in callback BaseSelectorEventLoop._read_from_self()\n",
      "handle: <Handle BaseSelectorEventLoop._read_from_self()>\n",
      "Traceback (most recent call last):\n",
      "  File \"C:\\Users\\Admin\\anaconda3\\lib\\asyncio\\events.py\", line 81, in _run\n",
      "    self._context.run(self._callback, *self._args)\n",
      "  File \"C:\\Users\\Admin\\anaconda3\\lib\\asyncio\\selector_events.py\", line 120, in _read_from_self\n",
      "    data = self._ssock.recv(4096)\n",
      "ConnectionResetError: [WinError 10054] An existing connection was forcibly closed by the remote host\n",
      "Exception in callback BaseSelectorEventLoop._read_from_self()\n",
      "handle: <Handle BaseSelectorEventLoop._read_from_self()>\n",
      "Traceback (most recent call last):\n",
      "  File \"C:\\Users\\Admin\\anaconda3\\lib\\asyncio\\events.py\", line 81, in _run\n",
      "    self._context.run(self._callback, *self._args)\n",
      "  File \"C:\\Users\\Admin\\anaconda3\\lib\\asyncio\\selector_events.py\", line 120, in _read_from_self\n",
      "    data = self._ssock.recv(4096)\n",
      "ConnectionResetError: [WinError 10054] An existing connection was forcibly closed by the remote host\n",
      "Exception in callback BaseSelectorEventLoop._read_from_self()\n",
      "handle: <Handle BaseSelectorEventLoop._read_from_self()>\n",
      "Traceback (most recent call last):\n",
      "  File \"C:\\Users\\Admin\\anaconda3\\lib\\asyncio\\events.py\", line 81, in _run\n",
      "    self._context.run(self._callback, *self._args)\n",
      "  File \"C:\\Users\\Admin\\anaconda3\\lib\\asyncio\\selector_events.py\", line 120, in _read_from_self\n",
      "    data = self._ssock.recv(4096)\n",
      "ConnectionResetError: [WinError 10054] An existing connection was forcibly closed by the remote host\n",
      "Exception in callback BaseSelectorEventLoop._read_from_self()\n",
      "handle: <Handle BaseSelectorEventLoop._read_from_self()>\n",
      "Traceback (most recent call last):\n",
      "  File \"C:\\Users\\Admin\\anaconda3\\lib\\asyncio\\events.py\", line 81, in _run\n",
      "    self._context.run(self._callback, *self._args)\n",
      "  File \"C:\\Users\\Admin\\anaconda3\\lib\\asyncio\\selector_events.py\", line 120, in _read_from_self\n",
      "    data = self._ssock.recv(4096)\n",
      "ConnectionResetError: [WinError 10054] An existing connection was forcibly closed by the remote host\n",
      "Exception in callback BaseSelectorEventLoop._read_from_self()\n",
      "handle: <Handle BaseSelectorEventLoop._read_from_self()>\n",
      "Traceback (most recent call last):\n",
      "  File \"C:\\Users\\Admin\\anaconda3\\lib\\asyncio\\events.py\", line 81, in _run\n",
      "    self._context.run(self._callback, *self._args)\n",
      "  File \"C:\\Users\\Admin\\anaconda3\\lib\\asyncio\\selector_events.py\", line 120, in _read_from_self\n",
      "    data = self._ssock.recv(4096)\n",
      "ConnectionResetError: [WinError 10054] An existing connection was forcibly closed by the remote host\n",
      "Exception in callback BaseSelectorEventLoop._read_from_self()\n",
      "handle: <Handle BaseSelectorEventLoop._read_from_self()>\n",
      "Traceback (most recent call last):\n",
      "  File \"C:\\Users\\Admin\\anaconda3\\lib\\asyncio\\events.py\", line 81, in _run\n",
      "    self._context.run(self._callback, *self._args)\n",
      "  File \"C:\\Users\\Admin\\anaconda3\\lib\\asyncio\\selector_events.py\", line 120, in _read_from_self\n",
      "    data = self._ssock.recv(4096)\n",
      "ConnectionResetError: [WinError 10054] An existing connection was forcibly closed by the remote host\n",
      "Exception in callback BaseSelectorEventLoop._read_from_self()\n",
      "handle: <Handle BaseSelectorEventLoop._read_from_self()>\n",
      "Traceback (most recent call last):\n",
      "  File \"C:\\Users\\Admin\\anaconda3\\lib\\asyncio\\events.py\", line 81, in _run\n",
      "    self._context.run(self._callback, *self._args)\n",
      "  File \"C:\\Users\\Admin\\anaconda3\\lib\\asyncio\\selector_events.py\", line 120, in _read_from_self\n",
      "    data = self._ssock.recv(4096)\n",
      "ConnectionResetError: [WinError 10054] An existing connection was forcibly closed by the remote host\n",
      "Exception in callback BaseSelectorEventLoop._read_from_self()\n",
      "handle: <Handle BaseSelectorEventLoop._read_from_self()>\n",
      "Traceback (most recent call last):\n",
      "  File \"C:\\Users\\Admin\\anaconda3\\lib\\asyncio\\events.py\", line 81, in _run\n",
      "    self._context.run(self._callback, *self._args)\n",
      "  File \"C:\\Users\\Admin\\anaconda3\\lib\\asyncio\\selector_events.py\", line 120, in _read_from_self\n",
      "    data = self._ssock.recv(4096)\n",
      "ConnectionResetError: [WinError 10054] An existing connection was forcibly closed by the remote host\n",
      "Exception in callback BaseSelectorEventLoop._read_from_self()\n",
      "handle: <Handle BaseSelectorEventLoop._read_from_self()>\n",
      "Traceback (most recent call last):\n",
      "  File \"C:\\Users\\Admin\\anaconda3\\lib\\asyncio\\events.py\", line 81, in _run\n",
      "    self._context.run(self._callback, *self._args)\n",
      "  File \"C:\\Users\\Admin\\anaconda3\\lib\\asyncio\\selector_events.py\", line 120, in _read_from_self\n",
      "    data = self._ssock.recv(4096)\n",
      "ConnectionResetError: [WinError 10054] An existing connection was forcibly closed by the remote host\n",
      "Exception in callback BaseSelectorEventLoop._read_from_self()\n",
      "handle: <Handle BaseSelectorEventLoop._read_from_self()>\n",
      "Traceback (most recent call last):\n",
      "  File \"C:\\Users\\Admin\\anaconda3\\lib\\asyncio\\events.py\", line 81, in _run\n",
      "    self._context.run(self._callback, *self._args)\n",
      "  File \"C:\\Users\\Admin\\anaconda3\\lib\\asyncio\\selector_events.py\", line 120, in _read_from_self\n",
      "    data = self._ssock.recv(4096)\n",
      "ConnectionResetError: [WinError 10054] An existing connection was forcibly closed by the remote host\n",
      "Exception in callback BaseSelectorEventLoop._read_from_self()\n",
      "handle: <Handle BaseSelectorEventLoop._read_from_self()>\n",
      "Traceback (most recent call last):\n",
      "  File \"C:\\Users\\Admin\\anaconda3\\lib\\asyncio\\events.py\", line 81, in _run\n",
      "    self._context.run(self._callback, *self._args)\n",
      "  File \"C:\\Users\\Admin\\anaconda3\\lib\\asyncio\\selector_events.py\", line 120, in _read_from_self\n",
      "    data = self._ssock.recv(4096)\n",
      "ConnectionResetError: [WinError 10054] An existing connection was forcibly closed by the remote host\n",
      "Exception in callback BaseSelectorEventLoop._read_from_self()\n",
      "handle: <Handle BaseSelectorEventLoop._read_from_self()>\n",
      "Traceback (most recent call last):\n",
      "  File \"C:\\Users\\Admin\\anaconda3\\lib\\asyncio\\events.py\", line 81, in _run\n",
      "    self._context.run(self._callback, *self._args)\n",
      "  File \"C:\\Users\\Admin\\anaconda3\\lib\\asyncio\\selector_events.py\", line 120, in _read_from_self\n",
      "    data = self._ssock.recv(4096)\n",
      "ConnectionResetError: [WinError 10054] An existing connection was forcibly closed by the remote host\n",
      "Exception in callback BaseSelectorEventLoop._read_from_self()\n",
      "handle: <Handle BaseSelectorEventLoop._read_from_self()>\n",
      "Traceback (most recent call last):\n",
      "  File \"C:\\Users\\Admin\\anaconda3\\lib\\asyncio\\events.py\", line 81, in _run\n",
      "    self._context.run(self._callback, *self._args)\n",
      "  File \"C:\\Users\\Admin\\anaconda3\\lib\\asyncio\\selector_events.py\", line 120, in _read_from_self\n",
      "    data = self._ssock.recv(4096)\n",
      "ConnectionResetError: [WinError 10054] An existing connection was forcibly closed by the remote host\n",
      "Exception in callback BaseSelectorEventLoop._read_from_self()\n",
      "handle: <Handle BaseSelectorEventLoop._read_from_self()>\n",
      "Traceback (most recent call last):\n",
      "  File \"C:\\Users\\Admin\\anaconda3\\lib\\asyncio\\events.py\", line 81, in _run\n",
      "    self._context.run(self._callback, *self._args)\n",
      "  File \"C:\\Users\\Admin\\anaconda3\\lib\\asyncio\\selector_events.py\", line 120, in _read_from_self\n",
      "    data = self._ssock.recv(4096)\n",
      "ConnectionResetError: [WinError 10054] An existing connection was forcibly closed by the remote host\n",
      "Exception in callback BaseSelectorEventLoop._read_from_self()\n",
      "handle: <Handle BaseSelectorEventLoop._read_from_self()>\n",
      "Traceback (most recent call last):\n",
      "  File \"C:\\Users\\Admin\\anaconda3\\lib\\asyncio\\events.py\", line 81, in _run\n",
      "    self._context.run(self._callback, *self._args)\n",
      "  File \"C:\\Users\\Admin\\anaconda3\\lib\\asyncio\\selector_events.py\", line 120, in _read_from_self\n",
      "    data = self._ssock.recv(4096)\n",
      "ConnectionResetError: [WinError 10054] An existing connection was forcibly closed by the remote host\n",
      "Exception in callback BaseSelectorEventLoop._read_from_self()\n",
      "handle: <Handle BaseSelectorEventLoop._read_from_self()>\n",
      "Traceback (most recent call last):\n",
      "  File \"C:\\Users\\Admin\\anaconda3\\lib\\asyncio\\events.py\", line 81, in _run\n",
      "    self._context.run(self._callback, *self._args)\n",
      "  File \"C:\\Users\\Admin\\anaconda3\\lib\\asyncio\\selector_events.py\", line 120, in _read_from_self\n",
      "    data = self._ssock.recv(4096)\n",
      "ConnectionResetError: [WinError 10054] An existing connection was forcibly closed by the remote host\n",
      "Exception in callback BaseSelectorEventLoop._read_from_self()\n",
      "handle: <Handle BaseSelectorEventLoop._read_from_self()>\n",
      "Traceback (most recent call last):\n",
      "  File \"C:\\Users\\Admin\\anaconda3\\lib\\asyncio\\events.py\", line 81, in _run\n",
      "    self._context.run(self._callback, *self._args)\n",
      "  File \"C:\\Users\\Admin\\anaconda3\\lib\\asyncio\\selector_events.py\", line 120, in _read_from_self\n",
      "    data = self._ssock.recv(4096)\n",
      "ConnectionResetError: [WinError 10054] An existing connection was forcibly closed by the remote host\n"
     ]
    },
    {
     "name": "stderr",
     "output_type": "stream",
     "text": [
      "Exception in callback BaseSelectorEventLoop._read_from_self()\n",
      "handle: <Handle BaseSelectorEventLoop._read_from_self()>\n",
      "Traceback (most recent call last):\n",
      "  File \"C:\\Users\\Admin\\anaconda3\\lib\\asyncio\\events.py\", line 81, in _run\n",
      "    self._context.run(self._callback, *self._args)\n",
      "  File \"C:\\Users\\Admin\\anaconda3\\lib\\asyncio\\selector_events.py\", line 120, in _read_from_self\n",
      "    data = self._ssock.recv(4096)\n",
      "ConnectionResetError: [WinError 10054] An existing connection was forcibly closed by the remote host\n",
      "Exception in callback BaseSelectorEventLoop._read_from_self()\n",
      "handle: <Handle BaseSelectorEventLoop._read_from_self()>\n",
      "Traceback (most recent call last):\n",
      "  File \"C:\\Users\\Admin\\anaconda3\\lib\\asyncio\\events.py\", line 81, in _run\n",
      "    self._context.run(self._callback, *self._args)\n",
      "  File \"C:\\Users\\Admin\\anaconda3\\lib\\asyncio\\selector_events.py\", line 120, in _read_from_self\n",
      "    data = self._ssock.recv(4096)\n",
      "ConnectionResetError: [WinError 10054] An existing connection was forcibly closed by the remote host\n",
      "Exception in callback BaseSelectorEventLoop._read_from_self()\n",
      "handle: <Handle BaseSelectorEventLoop._read_from_self()>\n",
      "Traceback (most recent call last):\n",
      "  File \"C:\\Users\\Admin\\anaconda3\\lib\\asyncio\\events.py\", line 81, in _run\n",
      "    self._context.run(self._callback, *self._args)\n",
      "  File \"C:\\Users\\Admin\\anaconda3\\lib\\asyncio\\selector_events.py\", line 120, in _read_from_self\n",
      "    data = self._ssock.recv(4096)\n",
      "ConnectionResetError: [WinError 10054] An existing connection was forcibly closed by the remote host\n",
      "Exception in callback BaseSelectorEventLoop._read_from_self()\n",
      "handle: <Handle BaseSelectorEventLoop._read_from_self()>\n",
      "Traceback (most recent call last):\n",
      "  File \"C:\\Users\\Admin\\anaconda3\\lib\\asyncio\\events.py\", line 81, in _run\n",
      "    self._context.run(self._callback, *self._args)\n",
      "  File \"C:\\Users\\Admin\\anaconda3\\lib\\asyncio\\selector_events.py\", line 120, in _read_from_self\n",
      "    data = self._ssock.recv(4096)\n",
      "ConnectionResetError: [WinError 10054] An existing connection was forcibly closed by the remote host\n",
      "Exception in callback BaseSelectorEventLoop._read_from_self()\n",
      "handle: <Handle BaseSelectorEventLoop._read_from_self()>\n",
      "Traceback (most recent call last):\n",
      "  File \"C:\\Users\\Admin\\anaconda3\\lib\\asyncio\\events.py\", line 81, in _run\n",
      "    self._context.run(self._callback, *self._args)\n",
      "  File \"C:\\Users\\Admin\\anaconda3\\lib\\asyncio\\selector_events.py\", line 120, in _read_from_self\n",
      "    data = self._ssock.recv(4096)\n",
      "ConnectionResetError: [WinError 10054] An existing connection was forcibly closed by the remote host\n",
      "Exception in callback BaseSelectorEventLoop._read_from_self()\n",
      "handle: <Handle BaseSelectorEventLoop._read_from_self()>\n",
      "Traceback (most recent call last):\n",
      "  File \"C:\\Users\\Admin\\anaconda3\\lib\\asyncio\\events.py\", line 81, in _run\n",
      "    self._context.run(self._callback, *self._args)\n",
      "  File \"C:\\Users\\Admin\\anaconda3\\lib\\asyncio\\selector_events.py\", line 120, in _read_from_self\n",
      "    data = self._ssock.recv(4096)\n",
      "ConnectionResetError: [WinError 10054] An existing connection was forcibly closed by the remote host\n",
      "Exception in callback BaseSelectorEventLoop._read_from_self()\n",
      "handle: <Handle BaseSelectorEventLoop._read_from_self()>\n",
      "Traceback (most recent call last):\n",
      "  File \"C:\\Users\\Admin\\anaconda3\\lib\\asyncio\\events.py\", line 81, in _run\n",
      "    self._context.run(self._callback, *self._args)\n",
      "  File \"C:\\Users\\Admin\\anaconda3\\lib\\asyncio\\selector_events.py\", line 120, in _read_from_self\n",
      "    data = self._ssock.recv(4096)\n",
      "ConnectionResetError: [WinError 10054] An existing connection was forcibly closed by the remote host\n",
      "Exception in callback BaseSelectorEventLoop._read_from_self()\n",
      "handle: <Handle BaseSelectorEventLoop._read_from_self()>\n",
      "Traceback (most recent call last):\n",
      "  File \"C:\\Users\\Admin\\anaconda3\\lib\\asyncio\\events.py\", line 81, in _run\n",
      "    self._context.run(self._callback, *self._args)\n",
      "  File \"C:\\Users\\Admin\\anaconda3\\lib\\asyncio\\selector_events.py\", line 120, in _read_from_self\n",
      "    data = self._ssock.recv(4096)\n",
      "ConnectionResetError: [WinError 10054] An existing connection was forcibly closed by the remote host\n",
      "Exception in callback BaseSelectorEventLoop._read_from_self()\n",
      "handle: <Handle BaseSelectorEventLoop._read_from_self()>\n",
      "Traceback (most recent call last):\n",
      "  File \"C:\\Users\\Admin\\anaconda3\\lib\\asyncio\\events.py\", line 81, in _run\n",
      "    self._context.run(self._callback, *self._args)\n",
      "  File \"C:\\Users\\Admin\\anaconda3\\lib\\asyncio\\selector_events.py\", line 120, in _read_from_self\n",
      "    data = self._ssock.recv(4096)\n",
      "ConnectionResetError: [WinError 10054] An existing connection was forcibly closed by the remote host\n",
      "Exception in callback BaseSelectorEventLoop._read_from_self()\n",
      "handle: <Handle BaseSelectorEventLoop._read_from_self()>\n",
      "Traceback (most recent call last):\n",
      "  File \"C:\\Users\\Admin\\anaconda3\\lib\\asyncio\\events.py\", line 81, in _run\n",
      "    self._context.run(self._callback, *self._args)\n",
      "  File \"C:\\Users\\Admin\\anaconda3\\lib\\asyncio\\selector_events.py\", line 120, in _read_from_self\n",
      "    data = self._ssock.recv(4096)\n",
      "ConnectionResetError: [WinError 10054] An existing connection was forcibly closed by the remote host\n",
      "Exception in callback BaseSelectorEventLoop._read_from_self()\n",
      "handle: <Handle BaseSelectorEventLoop._read_from_self()>\n",
      "Traceback (most recent call last):\n",
      "  File \"C:\\Users\\Admin\\anaconda3\\lib\\asyncio\\events.py\", line 81, in _run\n",
      "    self._context.run(self._callback, *self._args)\n",
      "  File \"C:\\Users\\Admin\\anaconda3\\lib\\asyncio\\selector_events.py\", line 120, in _read_from_self\n",
      "    data = self._ssock.recv(4096)\n",
      "ConnectionResetError: [WinError 10054] An existing connection was forcibly closed by the remote host\n",
      "Exception in callback BaseSelectorEventLoop._read_from_self()\n",
      "handle: <Handle BaseSelectorEventLoop._read_from_self()>\n",
      "Traceback (most recent call last):\n",
      "  File \"C:\\Users\\Admin\\anaconda3\\lib\\asyncio\\events.py\", line 81, in _run\n",
      "    self._context.run(self._callback, *self._args)\n",
      "  File \"C:\\Users\\Admin\\anaconda3\\lib\\asyncio\\selector_events.py\", line 120, in _read_from_self\n",
      "    data = self._ssock.recv(4096)\n",
      "ConnectionResetError: [WinError 10054] An existing connection was forcibly closed by the remote host\n",
      "Exception in callback BaseSelectorEventLoop._read_from_self()\n",
      "handle: <Handle BaseSelectorEventLoop._read_from_self()>\n",
      "Traceback (most recent call last):\n",
      "  File \"C:\\Users\\Admin\\anaconda3\\lib\\asyncio\\events.py\", line 81, in _run\n",
      "    self._context.run(self._callback, *self._args)\n",
      "  File \"C:\\Users\\Admin\\anaconda3\\lib\\asyncio\\selector_events.py\", line 120, in _read_from_self\n",
      "    data = self._ssock.recv(4096)\n",
      "ConnectionResetError: [WinError 10054] An existing connection was forcibly closed by the remote host\n",
      "Exception in callback BaseSelectorEventLoop._read_from_self()\n",
      "handle: <Handle BaseSelectorEventLoop._read_from_self()>\n",
      "Traceback (most recent call last):\n",
      "  File \"C:\\Users\\Admin\\anaconda3\\lib\\asyncio\\events.py\", line 81, in _run\n",
      "    self._context.run(self._callback, *self._args)\n",
      "  File \"C:\\Users\\Admin\\anaconda3\\lib\\asyncio\\selector_events.py\", line 120, in _read_from_self\n",
      "    data = self._ssock.recv(4096)\n",
      "ConnectionResetError: [WinError 10054] An existing connection was forcibly closed by the remote host\n",
      "Exception in callback BaseSelectorEventLoop._read_from_self()\n",
      "handle: <Handle BaseSelectorEventLoop._read_from_self()>\n",
      "Traceback (most recent call last):\n",
      "  File \"C:\\Users\\Admin\\anaconda3\\lib\\asyncio\\events.py\", line 81, in _run\n",
      "    self._context.run(self._callback, *self._args)\n",
      "  File \"C:\\Users\\Admin\\anaconda3\\lib\\asyncio\\selector_events.py\", line 120, in _read_from_self\n",
      "    data = self._ssock.recv(4096)\n",
      "ConnectionResetError: [WinError 10054] An existing connection was forcibly closed by the remote host\n",
      "Exception in callback BaseSelectorEventLoop._read_from_self()\n",
      "handle: <Handle BaseSelectorEventLoop._read_from_self()>\n",
      "Traceback (most recent call last):\n",
      "  File \"C:\\Users\\Admin\\anaconda3\\lib\\asyncio\\events.py\", line 81, in _run\n",
      "    self._context.run(self._callback, *self._args)\n",
      "  File \"C:\\Users\\Admin\\anaconda3\\lib\\asyncio\\selector_events.py\", line 120, in _read_from_self\n",
      "    data = self._ssock.recv(4096)\n",
      "ConnectionResetError: [WinError 10054] An existing connection was forcibly closed by the remote host\n",
      "Exception in callback BaseSelectorEventLoop._read_from_self()\n",
      "handle: <Handle BaseSelectorEventLoop._read_from_self()>\n",
      "Traceback (most recent call last):\n",
      "  File \"C:\\Users\\Admin\\anaconda3\\lib\\asyncio\\events.py\", line 81, in _run\n",
      "    self._context.run(self._callback, *self._args)\n",
      "  File \"C:\\Users\\Admin\\anaconda3\\lib\\asyncio\\selector_events.py\", line 120, in _read_from_self\n",
      "    data = self._ssock.recv(4096)\n",
      "ConnectionResetError: [WinError 10054] An existing connection was forcibly closed by the remote host\n"
     ]
    },
    {
     "name": "stderr",
     "output_type": "stream",
     "text": [
      "Exception in callback BaseSelectorEventLoop._read_from_self()\n",
      "handle: <Handle BaseSelectorEventLoop._read_from_self()>\n",
      "Traceback (most recent call last):\n",
      "  File \"C:\\Users\\Admin\\anaconda3\\lib\\asyncio\\events.py\", line 81, in _run\n",
      "    self._context.run(self._callback, *self._args)\n",
      "  File \"C:\\Users\\Admin\\anaconda3\\lib\\asyncio\\selector_events.py\", line 120, in _read_from_self\n",
      "    data = self._ssock.recv(4096)\n",
      "ConnectionResetError: [WinError 10054] An existing connection was forcibly closed by the remote host\n",
      "Exception in callback BaseSelectorEventLoop._read_from_self()\n",
      "handle: <Handle BaseSelectorEventLoop._read_from_self()>\n",
      "Traceback (most recent call last):\n",
      "  File \"C:\\Users\\Admin\\anaconda3\\lib\\asyncio\\events.py\", line 81, in _run\n",
      "    self._context.run(self._callback, *self._args)\n",
      "  File \"C:\\Users\\Admin\\anaconda3\\lib\\asyncio\\selector_events.py\", line 120, in _read_from_self\n",
      "    data = self._ssock.recv(4096)\n",
      "ConnectionResetError: [WinError 10054] An existing connection was forcibly closed by the remote host\n",
      "Exception in callback BaseSelectorEventLoop._read_from_self()\n",
      "handle: <Handle BaseSelectorEventLoop._read_from_self()>\n",
      "Traceback (most recent call last):\n",
      "  File \"C:\\Users\\Admin\\anaconda3\\lib\\asyncio\\events.py\", line 81, in _run\n",
      "    self._context.run(self._callback, *self._args)\n",
      "  File \"C:\\Users\\Admin\\anaconda3\\lib\\asyncio\\selector_events.py\", line 120, in _read_from_self\n",
      "    data = self._ssock.recv(4096)\n",
      "ConnectionResetError: [WinError 10054] An existing connection was forcibly closed by the remote host\n",
      "Exception in callback BaseSelectorEventLoop._read_from_self()\n",
      "handle: <Handle BaseSelectorEventLoop._read_from_self()>\n",
      "Traceback (most recent call last):\n",
      "  File \"C:\\Users\\Admin\\anaconda3\\lib\\asyncio\\events.py\", line 81, in _run\n",
      "    self._context.run(self._callback, *self._args)\n",
      "  File \"C:\\Users\\Admin\\anaconda3\\lib\\asyncio\\selector_events.py\", line 120, in _read_from_self\n",
      "    data = self._ssock.recv(4096)\n",
      "ConnectionResetError: [WinError 10054] An existing connection was forcibly closed by the remote host\n",
      "Exception in callback BaseSelectorEventLoop._read_from_self()\n",
      "handle: <Handle BaseSelectorEventLoop._read_from_self()>\n",
      "Traceback (most recent call last):\n",
      "  File \"C:\\Users\\Admin\\anaconda3\\lib\\asyncio\\events.py\", line 81, in _run\n",
      "    self._context.run(self._callback, *self._args)\n",
      "  File \"C:\\Users\\Admin\\anaconda3\\lib\\asyncio\\selector_events.py\", line 120, in _read_from_self\n",
      "    data = self._ssock.recv(4096)\n",
      "ConnectionResetError: [WinError 10054] An existing connection was forcibly closed by the remote host\n",
      "Exception in callback BaseSelectorEventLoop._read_from_self()\n",
      "handle: <Handle BaseSelectorEventLoop._read_from_self()>\n",
      "Traceback (most recent call last):\n",
      "  File \"C:\\Users\\Admin\\anaconda3\\lib\\asyncio\\events.py\", line 81, in _run\n",
      "    self._context.run(self._callback, *self._args)\n",
      "  File \"C:\\Users\\Admin\\anaconda3\\lib\\asyncio\\selector_events.py\", line 120, in _read_from_self\n",
      "    data = self._ssock.recv(4096)\n",
      "ConnectionResetError: [WinError 10054] An existing connection was forcibly closed by the remote host\n",
      "Exception in callback BaseSelectorEventLoop._read_from_self()\n",
      "handle: <Handle BaseSelectorEventLoop._read_from_self()>\n",
      "Traceback (most recent call last):\n",
      "  File \"C:\\Users\\Admin\\anaconda3\\lib\\asyncio\\events.py\", line 81, in _run\n",
      "    self._context.run(self._callback, *self._args)\n",
      "  File \"C:\\Users\\Admin\\anaconda3\\lib\\asyncio\\selector_events.py\", line 120, in _read_from_self\n",
      "    data = self._ssock.recv(4096)\n",
      "ConnectionResetError: [WinError 10054] An existing connection was forcibly closed by the remote host\n",
      "Exception in callback BaseSelectorEventLoop._read_from_self()\n",
      "handle: <Handle BaseSelectorEventLoop._read_from_self()>\n",
      "Traceback (most recent call last):\n",
      "  File \"C:\\Users\\Admin\\anaconda3\\lib\\asyncio\\events.py\", line 81, in _run\n",
      "    self._context.run(self._callback, *self._args)\n",
      "  File \"C:\\Users\\Admin\\anaconda3\\lib\\asyncio\\selector_events.py\", line 120, in _read_from_self\n",
      "    data = self._ssock.recv(4096)\n",
      "ConnectionResetError: [WinError 10054] An existing connection was forcibly closed by the remote host\n",
      "Exception in callback BaseSelectorEventLoop._read_from_self()\n",
      "handle: <Handle BaseSelectorEventLoop._read_from_self()>\n",
      "Traceback (most recent call last):\n",
      "  File \"C:\\Users\\Admin\\anaconda3\\lib\\asyncio\\events.py\", line 81, in _run\n",
      "    self._context.run(self._callback, *self._args)\n",
      "  File \"C:\\Users\\Admin\\anaconda3\\lib\\asyncio\\selector_events.py\", line 120, in _read_from_self\n",
      "    data = self._ssock.recv(4096)\n",
      "ConnectionResetError: [WinError 10054] An existing connection was forcibly closed by the remote host\n",
      "Exception in callback BaseSelectorEventLoop._read_from_self()\n",
      "handle: <Handle BaseSelectorEventLoop._read_from_self()>\n",
      "Traceback (most recent call last):\n",
      "  File \"C:\\Users\\Admin\\anaconda3\\lib\\asyncio\\events.py\", line 81, in _run\n",
      "    self._context.run(self._callback, *self._args)\n",
      "  File \"C:\\Users\\Admin\\anaconda3\\lib\\asyncio\\selector_events.py\", line 120, in _read_from_self\n",
      "    data = self._ssock.recv(4096)\n",
      "ConnectionResetError: [WinError 10054] An existing connection was forcibly closed by the remote host\n",
      "Exception in callback BaseSelectorEventLoop._read_from_self()\n",
      "handle: <Handle BaseSelectorEventLoop._read_from_self()>\n",
      "Traceback (most recent call last):\n",
      "  File \"C:\\Users\\Admin\\anaconda3\\lib\\asyncio\\events.py\", line 81, in _run\n",
      "    self._context.run(self._callback, *self._args)\n",
      "  File \"C:\\Users\\Admin\\anaconda3\\lib\\asyncio\\selector_events.py\", line 120, in _read_from_self\n",
      "    data = self._ssock.recv(4096)\n",
      "ConnectionResetError: [WinError 10054] An existing connection was forcibly closed by the remote host\n",
      "Exception in callback BaseSelectorEventLoop._read_from_self()\n",
      "handle: <Handle BaseSelectorEventLoop._read_from_self()>\n",
      "Traceback (most recent call last):\n",
      "  File \"C:\\Users\\Admin\\anaconda3\\lib\\asyncio\\events.py\", line 81, in _run\n",
      "    self._context.run(self._callback, *self._args)\n",
      "  File \"C:\\Users\\Admin\\anaconda3\\lib\\asyncio\\selector_events.py\", line 120, in _read_from_self\n",
      "    data = self._ssock.recv(4096)\n",
      "ConnectionResetError: [WinError 10054] An existing connection was forcibly closed by the remote host\n",
      "Exception in callback BaseSelectorEventLoop._read_from_self()\n",
      "handle: <Handle BaseSelectorEventLoop._read_from_self()>\n",
      "Traceback (most recent call last):\n",
      "  File \"C:\\Users\\Admin\\anaconda3\\lib\\asyncio\\events.py\", line 81, in _run\n",
      "    self._context.run(self._callback, *self._args)\n",
      "  File \"C:\\Users\\Admin\\anaconda3\\lib\\asyncio\\selector_events.py\", line 120, in _read_from_self\n",
      "    data = self._ssock.recv(4096)\n",
      "ConnectionResetError: [WinError 10054] An existing connection was forcibly closed by the remote host\n",
      "Exception in callback BaseSelectorEventLoop._read_from_self()\n",
      "handle: <Handle BaseSelectorEventLoop._read_from_self()>\n",
      "Traceback (most recent call last):\n",
      "  File \"C:\\Users\\Admin\\anaconda3\\lib\\asyncio\\events.py\", line 81, in _run\n",
      "    self._context.run(self._callback, *self._args)\n",
      "  File \"C:\\Users\\Admin\\anaconda3\\lib\\asyncio\\selector_events.py\", line 120, in _read_from_self\n",
      "    data = self._ssock.recv(4096)\n",
      "ConnectionResetError: [WinError 10054] An existing connection was forcibly closed by the remote host\n",
      "Exception in callback BaseSelectorEventLoop._read_from_self()\n",
      "handle: <Handle BaseSelectorEventLoop._read_from_self()>\n",
      "Traceback (most recent call last):\n",
      "  File \"C:\\Users\\Admin\\anaconda3\\lib\\asyncio\\events.py\", line 81, in _run\n",
      "    self._context.run(self._callback, *self._args)\n",
      "  File \"C:\\Users\\Admin\\anaconda3\\lib\\asyncio\\selector_events.py\", line 120, in _read_from_self\n",
      "    data = self._ssock.recv(4096)\n",
      "ConnectionResetError: [WinError 10054] An existing connection was forcibly closed by the remote host\n",
      "Exception in callback BaseSelectorEventLoop._read_from_self()\n",
      "handle: <Handle BaseSelectorEventLoop._read_from_self()>\n",
      "Traceback (most recent call last):\n",
      "  File \"C:\\Users\\Admin\\anaconda3\\lib\\asyncio\\events.py\", line 81, in _run\n",
      "    self._context.run(self._callback, *self._args)\n",
      "  File \"C:\\Users\\Admin\\anaconda3\\lib\\asyncio\\selector_events.py\", line 120, in _read_from_self\n",
      "    data = self._ssock.recv(4096)\n",
      "ConnectionResetError: [WinError 10054] An existing connection was forcibly closed by the remote host\n",
      "Exception in callback BaseSelectorEventLoop._read_from_self()\n",
      "handle: <Handle BaseSelectorEventLoop._read_from_self()>\n",
      "Traceback (most recent call last):\n",
      "  File \"C:\\Users\\Admin\\anaconda3\\lib\\asyncio\\events.py\", line 81, in _run\n",
      "    self._context.run(self._callback, *self._args)\n",
      "  File \"C:\\Users\\Admin\\anaconda3\\lib\\asyncio\\selector_events.py\", line 120, in _read_from_self\n",
      "    data = self._ssock.recv(4096)\n",
      "ConnectionResetError: [WinError 10054] An existing connection was forcibly closed by the remote host\n"
     ]
    },
    {
     "name": "stderr",
     "output_type": "stream",
     "text": [
      "Exception in callback BaseSelectorEventLoop._read_from_self()\n",
      "handle: <Handle BaseSelectorEventLoop._read_from_self()>\n",
      "Traceback (most recent call last):\n",
      "  File \"C:\\Users\\Admin\\anaconda3\\lib\\asyncio\\events.py\", line 81, in _run\n",
      "    self._context.run(self._callback, *self._args)\n",
      "  File \"C:\\Users\\Admin\\anaconda3\\lib\\asyncio\\selector_events.py\", line 120, in _read_from_self\n",
      "    data = self._ssock.recv(4096)\n",
      "ConnectionResetError: [WinError 10054] An existing connection was forcibly closed by the remote host\n",
      "Exception in callback BaseSelectorEventLoop._read_from_self()\n",
      "handle: <Handle BaseSelectorEventLoop._read_from_self()>\n",
      "Traceback (most recent call last):\n",
      "  File \"C:\\Users\\Admin\\anaconda3\\lib\\asyncio\\events.py\", line 81, in _run\n",
      "    self._context.run(self._callback, *self._args)\n",
      "  File \"C:\\Users\\Admin\\anaconda3\\lib\\asyncio\\selector_events.py\", line 120, in _read_from_self\n",
      "    data = self._ssock.recv(4096)\n",
      "ConnectionResetError: [WinError 10054] An existing connection was forcibly closed by the remote host\n",
      "Exception in callback BaseSelectorEventLoop._read_from_self()\n",
      "handle: <Handle BaseSelectorEventLoop._read_from_self()>\n",
      "Traceback (most recent call last):\n",
      "  File \"C:\\Users\\Admin\\anaconda3\\lib\\asyncio\\events.py\", line 81, in _run\n",
      "    self._context.run(self._callback, *self._args)\n",
      "  File \"C:\\Users\\Admin\\anaconda3\\lib\\asyncio\\selector_events.py\", line 120, in _read_from_self\n",
      "    data = self._ssock.recv(4096)\n",
      "ConnectionResetError: [WinError 10054] An existing connection was forcibly closed by the remote host\n",
      "Exception in callback BaseSelectorEventLoop._read_from_self()\n",
      "handle: <Handle BaseSelectorEventLoop._read_from_self()>\n",
      "Traceback (most recent call last):\n",
      "  File \"C:\\Users\\Admin\\anaconda3\\lib\\asyncio\\events.py\", line 81, in _run\n",
      "    self._context.run(self._callback, *self._args)\n",
      "  File \"C:\\Users\\Admin\\anaconda3\\lib\\asyncio\\selector_events.py\", line 120, in _read_from_self\n",
      "    data = self._ssock.recv(4096)\n",
      "ConnectionResetError: [WinError 10054] An existing connection was forcibly closed by the remote host\n",
      "Exception in callback BaseSelectorEventLoop._read_from_self()\n",
      "handle: <Handle BaseSelectorEventLoop._read_from_self()>\n",
      "Traceback (most recent call last):\n",
      "  File \"C:\\Users\\Admin\\anaconda3\\lib\\asyncio\\events.py\", line 81, in _run\n",
      "    self._context.run(self._callback, *self._args)\n",
      "  File \"C:\\Users\\Admin\\anaconda3\\lib\\asyncio\\selector_events.py\", line 120, in _read_from_self\n",
      "    data = self._ssock.recv(4096)\n",
      "ConnectionResetError: [WinError 10054] An existing connection was forcibly closed by the remote host\n",
      "Exception in callback BaseSelectorEventLoop._read_from_self()\n",
      "handle: <Handle BaseSelectorEventLoop._read_from_self()>\n",
      "Traceback (most recent call last):\n",
      "  File \"C:\\Users\\Admin\\anaconda3\\lib\\asyncio\\events.py\", line 81, in _run\n",
      "    self._context.run(self._callback, *self._args)\n",
      "  File \"C:\\Users\\Admin\\anaconda3\\lib\\asyncio\\selector_events.py\", line 120, in _read_from_self\n",
      "    data = self._ssock.recv(4096)\n",
      "ConnectionResetError: [WinError 10054] An existing connection was forcibly closed by the remote host\n",
      "Exception in callback BaseSelectorEventLoop._read_from_self()\n",
      "handle: <Handle BaseSelectorEventLoop._read_from_self()>\n",
      "Traceback (most recent call last):\n",
      "  File \"C:\\Users\\Admin\\anaconda3\\lib\\asyncio\\events.py\", line 81, in _run\n",
      "    self._context.run(self._callback, *self._args)\n",
      "  File \"C:\\Users\\Admin\\anaconda3\\lib\\asyncio\\selector_events.py\", line 120, in _read_from_self\n",
      "    data = self._ssock.recv(4096)\n",
      "ConnectionResetError: [WinError 10054] An existing connection was forcibly closed by the remote host\n",
      "Exception in callback BaseSelectorEventLoop._read_from_self()\n",
      "handle: <Handle BaseSelectorEventLoop._read_from_self()>\n",
      "Traceback (most recent call last):\n",
      "  File \"C:\\Users\\Admin\\anaconda3\\lib\\asyncio\\events.py\", line 81, in _run\n",
      "    self._context.run(self._callback, *self._args)\n",
      "  File \"C:\\Users\\Admin\\anaconda3\\lib\\asyncio\\selector_events.py\", line 120, in _read_from_self\n",
      "    data = self._ssock.recv(4096)\n",
      "ConnectionResetError: [WinError 10054] An existing connection was forcibly closed by the remote host\n",
      "Exception in callback BaseSelectorEventLoop._read_from_self()\n",
      "handle: <Handle BaseSelectorEventLoop._read_from_self()>\n",
      "Traceback (most recent call last):\n",
      "  File \"C:\\Users\\Admin\\anaconda3\\lib\\asyncio\\events.py\", line 81, in _run\n",
      "    self._context.run(self._callback, *self._args)\n",
      "  File \"C:\\Users\\Admin\\anaconda3\\lib\\asyncio\\selector_events.py\", line 120, in _read_from_self\n",
      "    data = self._ssock.recv(4096)\n",
      "ConnectionResetError: [WinError 10054] An existing connection was forcibly closed by the remote host\n",
      "Exception in callback BaseSelectorEventLoop._read_from_self()\n",
      "handle: <Handle BaseSelectorEventLoop._read_from_self()>\n",
      "Traceback (most recent call last):\n",
      "  File \"C:\\Users\\Admin\\anaconda3\\lib\\asyncio\\events.py\", line 81, in _run\n",
      "    self._context.run(self._callback, *self._args)\n",
      "  File \"C:\\Users\\Admin\\anaconda3\\lib\\asyncio\\selector_events.py\", line 120, in _read_from_self\n",
      "    data = self._ssock.recv(4096)\n",
      "ConnectionResetError: [WinError 10054] An existing connection was forcibly closed by the remote host\n",
      "Exception in callback BaseSelectorEventLoop._read_from_self()\n",
      "handle: <Handle BaseSelectorEventLoop._read_from_self()>\n",
      "Traceback (most recent call last):\n",
      "  File \"C:\\Users\\Admin\\anaconda3\\lib\\asyncio\\events.py\", line 81, in _run\n",
      "    self._context.run(self._callback, *self._args)\n",
      "  File \"C:\\Users\\Admin\\anaconda3\\lib\\asyncio\\selector_events.py\", line 120, in _read_from_self\n",
      "    data = self._ssock.recv(4096)\n",
      "ConnectionResetError: [WinError 10054] An existing connection was forcibly closed by the remote host\n",
      "Exception in callback BaseSelectorEventLoop._read_from_self()\n",
      "handle: <Handle BaseSelectorEventLoop._read_from_self()>\n",
      "Traceback (most recent call last):\n",
      "  File \"C:\\Users\\Admin\\anaconda3\\lib\\asyncio\\events.py\", line 81, in _run\n",
      "    self._context.run(self._callback, *self._args)\n",
      "  File \"C:\\Users\\Admin\\anaconda3\\lib\\asyncio\\selector_events.py\", line 120, in _read_from_self\n",
      "    data = self._ssock.recv(4096)\n",
      "ConnectionResetError: [WinError 10054] An existing connection was forcibly closed by the remote host\n",
      "Exception in callback BaseSelectorEventLoop._read_from_self()\n",
      "handle: <Handle BaseSelectorEventLoop._read_from_self()>\n",
      "Traceback (most recent call last):\n",
      "  File \"C:\\Users\\Admin\\anaconda3\\lib\\asyncio\\events.py\", line 81, in _run\n",
      "    self._context.run(self._callback, *self._args)\n",
      "  File \"C:\\Users\\Admin\\anaconda3\\lib\\asyncio\\selector_events.py\", line 120, in _read_from_self\n",
      "    data = self._ssock.recv(4096)\n",
      "ConnectionResetError: [WinError 10054] An existing connection was forcibly closed by the remote host\n",
      "Exception in callback BaseSelectorEventLoop._read_from_self()\n",
      "handle: <Handle BaseSelectorEventLoop._read_from_self()>\n",
      "Traceback (most recent call last):\n",
      "  File \"C:\\Users\\Admin\\anaconda3\\lib\\asyncio\\events.py\", line 81, in _run\n",
      "    self._context.run(self._callback, *self._args)\n",
      "  File \"C:\\Users\\Admin\\anaconda3\\lib\\asyncio\\selector_events.py\", line 120, in _read_from_self\n",
      "    data = self._ssock.recv(4096)\n",
      "ConnectionResetError: [WinError 10054] An existing connection was forcibly closed by the remote host\n",
      "Exception in callback BaseSelectorEventLoop._read_from_self()\n",
      "handle: <Handle BaseSelectorEventLoop._read_from_self()>\n",
      "Traceback (most recent call last):\n",
      "  File \"C:\\Users\\Admin\\anaconda3\\lib\\asyncio\\events.py\", line 81, in _run\n",
      "    self._context.run(self._callback, *self._args)\n",
      "  File \"C:\\Users\\Admin\\anaconda3\\lib\\asyncio\\selector_events.py\", line 120, in _read_from_self\n",
      "    data = self._ssock.recv(4096)\n",
      "ConnectionResetError: [WinError 10054] An existing connection was forcibly closed by the remote host\n",
      "Exception in callback BaseSelectorEventLoop._read_from_self()\n",
      "handle: <Handle BaseSelectorEventLoop._read_from_self()>\n",
      "Traceback (most recent call last):\n",
      "  File \"C:\\Users\\Admin\\anaconda3\\lib\\asyncio\\events.py\", line 81, in _run\n",
      "    self._context.run(self._callback, *self._args)\n",
      "  File \"C:\\Users\\Admin\\anaconda3\\lib\\asyncio\\selector_events.py\", line 120, in _read_from_self\n",
      "    data = self._ssock.recv(4096)\n",
      "ConnectionResetError: [WinError 10054] An existing connection was forcibly closed by the remote host\n",
      "Exception in callback BaseSelectorEventLoop._read_from_self()\n",
      "handle: <Handle BaseSelectorEventLoop._read_from_self()>\n",
      "Traceback (most recent call last):\n",
      "  File \"C:\\Users\\Admin\\anaconda3\\lib\\asyncio\\events.py\", line 81, in _run\n",
      "    self._context.run(self._callback, *self._args)\n",
      "  File \"C:\\Users\\Admin\\anaconda3\\lib\\asyncio\\selector_events.py\", line 120, in _read_from_self\n",
      "    data = self._ssock.recv(4096)\n",
      "ConnectionResetError: [WinError 10054] An existing connection was forcibly closed by the remote host\n"
     ]
    },
    {
     "name": "stderr",
     "output_type": "stream",
     "text": [
      "Exception in callback BaseSelectorEventLoop._read_from_self()\n",
      "handle: <Handle BaseSelectorEventLoop._read_from_self()>\n",
      "Traceback (most recent call last):\n",
      "  File \"C:\\Users\\Admin\\anaconda3\\lib\\asyncio\\events.py\", line 81, in _run\n",
      "    self._context.run(self._callback, *self._args)\n",
      "  File \"C:\\Users\\Admin\\anaconda3\\lib\\asyncio\\selector_events.py\", line 120, in _read_from_self\n",
      "    data = self._ssock.recv(4096)\n",
      "ConnectionResetError: [WinError 10054] An existing connection was forcibly closed by the remote host\n",
      "Exception in callback BaseSelectorEventLoop._read_from_self()\n",
      "handle: <Handle BaseSelectorEventLoop._read_from_self()>\n",
      "Traceback (most recent call last):\n",
      "  File \"C:\\Users\\Admin\\anaconda3\\lib\\asyncio\\events.py\", line 81, in _run\n",
      "    self._context.run(self._callback, *self._args)\n",
      "  File \"C:\\Users\\Admin\\anaconda3\\lib\\asyncio\\selector_events.py\", line 120, in _read_from_self\n",
      "    data = self._ssock.recv(4096)\n",
      "ConnectionResetError: [WinError 10054] An existing connection was forcibly closed by the remote host\n",
      "Exception in callback BaseSelectorEventLoop._read_from_self()\n",
      "handle: <Handle BaseSelectorEventLoop._read_from_self()>\n",
      "Traceback (most recent call last):\n",
      "  File \"C:\\Users\\Admin\\anaconda3\\lib\\asyncio\\events.py\", line 81, in _run\n",
      "    self._context.run(self._callback, *self._args)\n",
      "  File \"C:\\Users\\Admin\\anaconda3\\lib\\asyncio\\selector_events.py\", line 120, in _read_from_self\n",
      "    data = self._ssock.recv(4096)\n",
      "ConnectionResetError: [WinError 10054] An existing connection was forcibly closed by the remote host\n",
      "Exception in callback BaseSelectorEventLoop._read_from_self()\n",
      "handle: <Handle BaseSelectorEventLoop._read_from_self()>\n",
      "Traceback (most recent call last):\n",
      "  File \"C:\\Users\\Admin\\anaconda3\\lib\\asyncio\\events.py\", line 81, in _run\n",
      "    self._context.run(self._callback, *self._args)\n",
      "  File \"C:\\Users\\Admin\\anaconda3\\lib\\asyncio\\selector_events.py\", line 120, in _read_from_self\n",
      "    data = self._ssock.recv(4096)\n",
      "ConnectionResetError: [WinError 10054] An existing connection was forcibly closed by the remote host\n",
      "Exception in callback BaseSelectorEventLoop._read_from_self()\n",
      "handle: <Handle BaseSelectorEventLoop._read_from_self()>\n",
      "Traceback (most recent call last):\n",
      "  File \"C:\\Users\\Admin\\anaconda3\\lib\\asyncio\\events.py\", line 81, in _run\n",
      "    self._context.run(self._callback, *self._args)\n",
      "  File \"C:\\Users\\Admin\\anaconda3\\lib\\asyncio\\selector_events.py\", line 120, in _read_from_self\n",
      "    data = self._ssock.recv(4096)\n",
      "ConnectionResetError: [WinError 10054] An existing connection was forcibly closed by the remote host\n",
      "Exception in callback BaseSelectorEventLoop._read_from_self()\n",
      "handle: <Handle BaseSelectorEventLoop._read_from_self()>\n",
      "Traceback (most recent call last):\n",
      "  File \"C:\\Users\\Admin\\anaconda3\\lib\\asyncio\\events.py\", line 81, in _run\n",
      "    self._context.run(self._callback, *self._args)\n",
      "  File \"C:\\Users\\Admin\\anaconda3\\lib\\asyncio\\selector_events.py\", line 120, in _read_from_self\n",
      "    data = self._ssock.recv(4096)\n",
      "ConnectionResetError: [WinError 10054] An existing connection was forcibly closed by the remote host\n",
      "Exception in callback BaseSelectorEventLoop._read_from_self()\n",
      "handle: <Handle BaseSelectorEventLoop._read_from_self()>\n",
      "Traceback (most recent call last):\n",
      "  File \"C:\\Users\\Admin\\anaconda3\\lib\\asyncio\\events.py\", line 81, in _run\n",
      "    self._context.run(self._callback, *self._args)\n",
      "  File \"C:\\Users\\Admin\\anaconda3\\lib\\asyncio\\selector_events.py\", line 120, in _read_from_self\n",
      "    data = self._ssock.recv(4096)\n",
      "ConnectionResetError: [WinError 10054] An existing connection was forcibly closed by the remote host\n",
      "Exception in callback BaseSelectorEventLoop._read_from_self()\n",
      "handle: <Handle BaseSelectorEventLoop._read_from_self()>\n",
      "Traceback (most recent call last):\n",
      "  File \"C:\\Users\\Admin\\anaconda3\\lib\\asyncio\\events.py\", line 81, in _run\n",
      "    self._context.run(self._callback, *self._args)\n",
      "  File \"C:\\Users\\Admin\\anaconda3\\lib\\asyncio\\selector_events.py\", line 120, in _read_from_self\n",
      "    data = self._ssock.recv(4096)\n",
      "ConnectionResetError: [WinError 10054] An existing connection was forcibly closed by the remote host\n",
      "Exception in callback BaseSelectorEventLoop._read_from_self()\n",
      "handle: <Handle BaseSelectorEventLoop._read_from_self()>\n",
      "Traceback (most recent call last):\n",
      "  File \"C:\\Users\\Admin\\anaconda3\\lib\\asyncio\\events.py\", line 81, in _run\n",
      "    self._context.run(self._callback, *self._args)\n",
      "  File \"C:\\Users\\Admin\\anaconda3\\lib\\asyncio\\selector_events.py\", line 120, in _read_from_self\n",
      "    data = self._ssock.recv(4096)\n",
      "ConnectionResetError: [WinError 10054] An existing connection was forcibly closed by the remote host\n",
      "Exception in callback BaseSelectorEventLoop._read_from_self()\n",
      "handle: <Handle BaseSelectorEventLoop._read_from_self()>\n",
      "Traceback (most recent call last):\n",
      "  File \"C:\\Users\\Admin\\anaconda3\\lib\\asyncio\\events.py\", line 81, in _run\n",
      "    self._context.run(self._callback, *self._args)\n",
      "  File \"C:\\Users\\Admin\\anaconda3\\lib\\asyncio\\selector_events.py\", line 120, in _read_from_self\n",
      "    data = self._ssock.recv(4096)\n",
      "ConnectionResetError: [WinError 10054] An existing connection was forcibly closed by the remote host\n",
      "Exception in callback BaseSelectorEventLoop._read_from_self()\n",
      "handle: <Handle BaseSelectorEventLoop._read_from_self()>\n",
      "Traceback (most recent call last):\n",
      "  File \"C:\\Users\\Admin\\anaconda3\\lib\\asyncio\\events.py\", line 81, in _run\n",
      "    self._context.run(self._callback, *self._args)\n",
      "  File \"C:\\Users\\Admin\\anaconda3\\lib\\asyncio\\selector_events.py\", line 120, in _read_from_self\n",
      "    data = self._ssock.recv(4096)\n",
      "ConnectionResetError: [WinError 10054] An existing connection was forcibly closed by the remote host\n",
      "Exception in callback BaseSelectorEventLoop._read_from_self()\n",
      "handle: <Handle BaseSelectorEventLoop._read_from_self()>\n",
      "Traceback (most recent call last):\n",
      "  File \"C:\\Users\\Admin\\anaconda3\\lib\\asyncio\\events.py\", line 81, in _run\n",
      "    self._context.run(self._callback, *self._args)\n",
      "  File \"C:\\Users\\Admin\\anaconda3\\lib\\asyncio\\selector_events.py\", line 120, in _read_from_self\n",
      "    data = self._ssock.recv(4096)\n",
      "ConnectionResetError: [WinError 10054] An existing connection was forcibly closed by the remote host\n",
      "Exception in callback BaseSelectorEventLoop._read_from_self()\n",
      "handle: <Handle BaseSelectorEventLoop._read_from_self()>\n",
      "Traceback (most recent call last):\n",
      "  File \"C:\\Users\\Admin\\anaconda3\\lib\\asyncio\\events.py\", line 81, in _run\n",
      "    self._context.run(self._callback, *self._args)\n",
      "  File \"C:\\Users\\Admin\\anaconda3\\lib\\asyncio\\selector_events.py\", line 120, in _read_from_self\n",
      "    data = self._ssock.recv(4096)\n",
      "ConnectionResetError: [WinError 10054] An existing connection was forcibly closed by the remote host\n",
      "Exception in callback BaseSelectorEventLoop._read_from_self()\n",
      "handle: <Handle BaseSelectorEventLoop._read_from_self()>\n",
      "Traceback (most recent call last):\n",
      "  File \"C:\\Users\\Admin\\anaconda3\\lib\\asyncio\\events.py\", line 81, in _run\n",
      "    self._context.run(self._callback, *self._args)\n",
      "  File \"C:\\Users\\Admin\\anaconda3\\lib\\asyncio\\selector_events.py\", line 120, in _read_from_self\n",
      "    data = self._ssock.recv(4096)\n",
      "ConnectionResetError: [WinError 10054] An existing connection was forcibly closed by the remote host\n",
      "Exception in callback BaseSelectorEventLoop._read_from_self()\n",
      "handle: <Handle BaseSelectorEventLoop._read_from_self()>\n",
      "Traceback (most recent call last):\n",
      "  File \"C:\\Users\\Admin\\anaconda3\\lib\\asyncio\\events.py\", line 81, in _run\n",
      "    self._context.run(self._callback, *self._args)\n",
      "  File \"C:\\Users\\Admin\\anaconda3\\lib\\asyncio\\selector_events.py\", line 120, in _read_from_self\n",
      "    data = self._ssock.recv(4096)\n",
      "ConnectionResetError: [WinError 10054] An existing connection was forcibly closed by the remote host\n",
      "Exception in callback BaseSelectorEventLoop._read_from_self()\n",
      "handle: <Handle BaseSelectorEventLoop._read_from_self()>\n",
      "Traceback (most recent call last):\n",
      "  File \"C:\\Users\\Admin\\anaconda3\\lib\\asyncio\\events.py\", line 81, in _run\n",
      "    self._context.run(self._callback, *self._args)\n",
      "  File \"C:\\Users\\Admin\\anaconda3\\lib\\asyncio\\selector_events.py\", line 120, in _read_from_self\n",
      "    data = self._ssock.recv(4096)\n",
      "ConnectionResetError: [WinError 10054] An existing connection was forcibly closed by the remote host\n",
      "Exception in callback BaseSelectorEventLoop._read_from_self()\n",
      "handle: <Handle BaseSelectorEventLoop._read_from_self()>\n",
      "Traceback (most recent call last):\n",
      "  File \"C:\\Users\\Admin\\anaconda3\\lib\\asyncio\\events.py\", line 81, in _run\n",
      "    self._context.run(self._callback, *self._args)\n",
      "  File \"C:\\Users\\Admin\\anaconda3\\lib\\asyncio\\selector_events.py\", line 120, in _read_from_self\n",
      "    data = self._ssock.recv(4096)\n",
      "ConnectionResetError: [WinError 10054] An existing connection was forcibly closed by the remote host\n"
     ]
    },
    {
     "name": "stderr",
     "output_type": "stream",
     "text": [
      "Exception in callback BaseSelectorEventLoop._read_from_self()\n",
      "handle: <Handle BaseSelectorEventLoop._read_from_self()>\n",
      "Traceback (most recent call last):\n",
      "  File \"C:\\Users\\Admin\\anaconda3\\lib\\asyncio\\events.py\", line 81, in _run\n",
      "    self._context.run(self._callback, *self._args)\n",
      "  File \"C:\\Users\\Admin\\anaconda3\\lib\\asyncio\\selector_events.py\", line 120, in _read_from_self\n",
      "    data = self._ssock.recv(4096)\n",
      "ConnectionResetError: [WinError 10054] An existing connection was forcibly closed by the remote host\n",
      "Exception in callback BaseSelectorEventLoop._read_from_self()\n",
      "handle: <Handle BaseSelectorEventLoop._read_from_self()>\n",
      "Traceback (most recent call last):\n",
      "  File \"C:\\Users\\Admin\\anaconda3\\lib\\asyncio\\events.py\", line 81, in _run\n",
      "    self._context.run(self._callback, *self._args)\n",
      "  File \"C:\\Users\\Admin\\anaconda3\\lib\\asyncio\\selector_events.py\", line 120, in _read_from_self\n",
      "    data = self._ssock.recv(4096)\n",
      "ConnectionResetError: [WinError 10054] An existing connection was forcibly closed by the remote host\n",
      "Exception in callback BaseSelectorEventLoop._read_from_self()\n",
      "handle: <Handle BaseSelectorEventLoop._read_from_self()>\n",
      "Traceback (most recent call last):\n",
      "  File \"C:\\Users\\Admin\\anaconda3\\lib\\asyncio\\events.py\", line 81, in _run\n",
      "    self._context.run(self._callback, *self._args)\n",
      "  File \"C:\\Users\\Admin\\anaconda3\\lib\\asyncio\\selector_events.py\", line 120, in _read_from_self\n",
      "    data = self._ssock.recv(4096)\n",
      "ConnectionResetError: [WinError 10054] An existing connection was forcibly closed by the remote host\n",
      "Exception in callback BaseSelectorEventLoop._read_from_self()\n",
      "handle: <Handle BaseSelectorEventLoop._read_from_self()>\n",
      "Traceback (most recent call last):\n",
      "  File \"C:\\Users\\Admin\\anaconda3\\lib\\asyncio\\events.py\", line 81, in _run\n",
      "    self._context.run(self._callback, *self._args)\n",
      "  File \"C:\\Users\\Admin\\anaconda3\\lib\\asyncio\\selector_events.py\", line 120, in _read_from_self\n",
      "    data = self._ssock.recv(4096)\n",
      "ConnectionResetError: [WinError 10054] An existing connection was forcibly closed by the remote host\n",
      "Exception in callback BaseSelectorEventLoop._read_from_self()\n",
      "handle: <Handle BaseSelectorEventLoop._read_from_self()>\n",
      "Traceback (most recent call last):\n",
      "  File \"C:\\Users\\Admin\\anaconda3\\lib\\asyncio\\events.py\", line 81, in _run\n",
      "    self._context.run(self._callback, *self._args)\n",
      "  File \"C:\\Users\\Admin\\anaconda3\\lib\\asyncio\\selector_events.py\", line 120, in _read_from_self\n",
      "    data = self._ssock.recv(4096)\n",
      "ConnectionResetError: [WinError 10054] An existing connection was forcibly closed by the remote host\n",
      "Exception in callback BaseSelectorEventLoop._read_from_self()\n",
      "handle: <Handle BaseSelectorEventLoop._read_from_self()>\n",
      "Traceback (most recent call last):\n",
      "  File \"C:\\Users\\Admin\\anaconda3\\lib\\asyncio\\events.py\", line 81, in _run\n",
      "    self._context.run(self._callback, *self._args)\n",
      "  File \"C:\\Users\\Admin\\anaconda3\\lib\\asyncio\\selector_events.py\", line 120, in _read_from_self\n",
      "    data = self._ssock.recv(4096)\n",
      "ConnectionResetError: [WinError 10054] An existing connection was forcibly closed by the remote host\n",
      "Exception in callback BaseSelectorEventLoop._read_from_self()\n",
      "handle: <Handle BaseSelectorEventLoop._read_from_self()>\n",
      "Traceback (most recent call last):\n",
      "  File \"C:\\Users\\Admin\\anaconda3\\lib\\asyncio\\events.py\", line 81, in _run\n",
      "    self._context.run(self._callback, *self._args)\n",
      "  File \"C:\\Users\\Admin\\anaconda3\\lib\\asyncio\\selector_events.py\", line 120, in _read_from_self\n",
      "    data = self._ssock.recv(4096)\n",
      "ConnectionResetError: [WinError 10054] An existing connection was forcibly closed by the remote host\n",
      "Exception in callback BaseSelectorEventLoop._read_from_self()\n",
      "handle: <Handle BaseSelectorEventLoop._read_from_self()>\n",
      "Traceback (most recent call last):\n",
      "  File \"C:\\Users\\Admin\\anaconda3\\lib\\asyncio\\events.py\", line 81, in _run\n",
      "    self._context.run(self._callback, *self._args)\n",
      "  File \"C:\\Users\\Admin\\anaconda3\\lib\\asyncio\\selector_events.py\", line 120, in _read_from_self\n",
      "    data = self._ssock.recv(4096)\n",
      "ConnectionResetError: [WinError 10054] An existing connection was forcibly closed by the remote host\n",
      "Exception in callback BaseSelectorEventLoop._read_from_self()\n",
      "handle: <Handle BaseSelectorEventLoop._read_from_self()>\n",
      "Traceback (most recent call last):\n",
      "  File \"C:\\Users\\Admin\\anaconda3\\lib\\asyncio\\events.py\", line 81, in _run\n",
      "    self._context.run(self._callback, *self._args)\n",
      "  File \"C:\\Users\\Admin\\anaconda3\\lib\\asyncio\\selector_events.py\", line 120, in _read_from_self\n",
      "    data = self._ssock.recv(4096)\n",
      "ConnectionResetError: [WinError 10054] An existing connection was forcibly closed by the remote host\n",
      "Exception in callback BaseSelectorEventLoop._read_from_self()\n",
      "handle: <Handle BaseSelectorEventLoop._read_from_self()>\n",
      "Traceback (most recent call last):\n",
      "  File \"C:\\Users\\Admin\\anaconda3\\lib\\asyncio\\events.py\", line 81, in _run\n",
      "    self._context.run(self._callback, *self._args)\n",
      "  File \"C:\\Users\\Admin\\anaconda3\\lib\\asyncio\\selector_events.py\", line 120, in _read_from_self\n",
      "    data = self._ssock.recv(4096)\n",
      "ConnectionResetError: [WinError 10054] An existing connection was forcibly closed by the remote host\n",
      "Exception in callback BaseSelectorEventLoop._read_from_self()\n",
      "handle: <Handle BaseSelectorEventLoop._read_from_self()>\n",
      "Traceback (most recent call last):\n",
      "  File \"C:\\Users\\Admin\\anaconda3\\lib\\asyncio\\events.py\", line 81, in _run\n",
      "    self._context.run(self._callback, *self._args)\n",
      "  File \"C:\\Users\\Admin\\anaconda3\\lib\\asyncio\\selector_events.py\", line 120, in _read_from_self\n",
      "    data = self._ssock.recv(4096)\n",
      "ConnectionResetError: [WinError 10054] An existing connection was forcibly closed by the remote host\n",
      "Exception in callback BaseSelectorEventLoop._read_from_self()\n",
      "handle: <Handle BaseSelectorEventLoop._read_from_self()>\n",
      "Traceback (most recent call last):\n",
      "  File \"C:\\Users\\Admin\\anaconda3\\lib\\asyncio\\events.py\", line 81, in _run\n",
      "    self._context.run(self._callback, *self._args)\n",
      "  File \"C:\\Users\\Admin\\anaconda3\\lib\\asyncio\\selector_events.py\", line 120, in _read_from_self\n",
      "    data = self._ssock.recv(4096)\n",
      "ConnectionResetError: [WinError 10054] An existing connection was forcibly closed by the remote host\n",
      "Exception in callback BaseSelectorEventLoop._read_from_self()\n",
      "handle: <Handle BaseSelectorEventLoop._read_from_self()>\n",
      "Traceback (most recent call last):\n",
      "  File \"C:\\Users\\Admin\\anaconda3\\lib\\asyncio\\events.py\", line 81, in _run\n",
      "    self._context.run(self._callback, *self._args)\n",
      "  File \"C:\\Users\\Admin\\anaconda3\\lib\\asyncio\\selector_events.py\", line 120, in _read_from_self\n",
      "    data = self._ssock.recv(4096)\n",
      "ConnectionResetError: [WinError 10054] An existing connection was forcibly closed by the remote host\n",
      "Exception in callback BaseSelectorEventLoop._read_from_self()\n",
      "handle: <Handle BaseSelectorEventLoop._read_from_self()>\n",
      "Traceback (most recent call last):\n",
      "  File \"C:\\Users\\Admin\\anaconda3\\lib\\asyncio\\events.py\", line 81, in _run\n",
      "    self._context.run(self._callback, *self._args)\n",
      "  File \"C:\\Users\\Admin\\anaconda3\\lib\\asyncio\\selector_events.py\", line 120, in _read_from_self\n",
      "    data = self._ssock.recv(4096)\n",
      "ConnectionResetError: [WinError 10054] An existing connection was forcibly closed by the remote host\n",
      "Exception in callback BaseSelectorEventLoop._read_from_self()\n",
      "handle: <Handle BaseSelectorEventLoop._read_from_self()>\n",
      "Traceback (most recent call last):\n",
      "  File \"C:\\Users\\Admin\\anaconda3\\lib\\asyncio\\events.py\", line 81, in _run\n",
      "    self._context.run(self._callback, *self._args)\n",
      "  File \"C:\\Users\\Admin\\anaconda3\\lib\\asyncio\\selector_events.py\", line 120, in _read_from_self\n",
      "    data = self._ssock.recv(4096)\n",
      "ConnectionResetError: [WinError 10054] An existing connection was forcibly closed by the remote host\n",
      "Exception in callback BaseSelectorEventLoop._read_from_self()\n",
      "handle: <Handle BaseSelectorEventLoop._read_from_self()>\n",
      "Traceback (most recent call last):\n",
      "  File \"C:\\Users\\Admin\\anaconda3\\lib\\asyncio\\events.py\", line 81, in _run\n",
      "    self._context.run(self._callback, *self._args)\n",
      "  File \"C:\\Users\\Admin\\anaconda3\\lib\\asyncio\\selector_events.py\", line 120, in _read_from_self\n",
      "    data = self._ssock.recv(4096)\n",
      "ConnectionResetError: [WinError 10054] An existing connection was forcibly closed by the remote host\n",
      "Exception in callback BaseSelectorEventLoop._read_from_self()\n",
      "handle: <Handle BaseSelectorEventLoop._read_from_self()>\n",
      "Traceback (most recent call last):\n",
      "  File \"C:\\Users\\Admin\\anaconda3\\lib\\asyncio\\events.py\", line 81, in _run\n",
      "    self._context.run(self._callback, *self._args)\n",
      "  File \"C:\\Users\\Admin\\anaconda3\\lib\\asyncio\\selector_events.py\", line 120, in _read_from_self\n",
      "    data = self._ssock.recv(4096)\n",
      "ConnectionResetError: [WinError 10054] An existing connection was forcibly closed by the remote host\n"
     ]
    },
    {
     "name": "stderr",
     "output_type": "stream",
     "text": [
      "Exception in callback BaseSelectorEventLoop._read_from_self()\n",
      "handle: <Handle BaseSelectorEventLoop._read_from_self()>\n",
      "Traceback (most recent call last):\n",
      "  File \"C:\\Users\\Admin\\anaconda3\\lib\\asyncio\\events.py\", line 81, in _run\n",
      "    self._context.run(self._callback, *self._args)\n",
      "  File \"C:\\Users\\Admin\\anaconda3\\lib\\asyncio\\selector_events.py\", line 120, in _read_from_self\n",
      "    data = self._ssock.recv(4096)\n",
      "ConnectionResetError: [WinError 10054] An existing connection was forcibly closed by the remote host\n",
      "Exception in callback BaseSelectorEventLoop._read_from_self()\n",
      "handle: <Handle BaseSelectorEventLoop._read_from_self()>\n",
      "Traceback (most recent call last):\n",
      "  File \"C:\\Users\\Admin\\anaconda3\\lib\\asyncio\\events.py\", line 81, in _run\n",
      "    self._context.run(self._callback, *self._args)\n",
      "  File \"C:\\Users\\Admin\\anaconda3\\lib\\asyncio\\selector_events.py\", line 120, in _read_from_self\n",
      "    data = self._ssock.recv(4096)\n",
      "ConnectionResetError: [WinError 10054] An existing connection was forcibly closed by the remote host\n",
      "Exception in callback BaseSelectorEventLoop._read_from_self()\n",
      "handle: <Handle BaseSelectorEventLoop._read_from_self()>\n",
      "Traceback (most recent call last):\n",
      "  File \"C:\\Users\\Admin\\anaconda3\\lib\\asyncio\\events.py\", line 81, in _run\n",
      "    self._context.run(self._callback, *self._args)\n",
      "  File \"C:\\Users\\Admin\\anaconda3\\lib\\asyncio\\selector_events.py\", line 120, in _read_from_self\n",
      "    data = self._ssock.recv(4096)\n",
      "ConnectionResetError: [WinError 10054] An existing connection was forcibly closed by the remote host\n",
      "Exception in callback BaseSelectorEventLoop._read_from_self()\n",
      "handle: <Handle BaseSelectorEventLoop._read_from_self()>\n",
      "Traceback (most recent call last):\n",
      "  File \"C:\\Users\\Admin\\anaconda3\\lib\\asyncio\\events.py\", line 81, in _run\n",
      "    self._context.run(self._callback, *self._args)\n",
      "  File \"C:\\Users\\Admin\\anaconda3\\lib\\asyncio\\selector_events.py\", line 120, in _read_from_self\n",
      "    data = self._ssock.recv(4096)\n",
      "ConnectionResetError: [WinError 10054] An existing connection was forcibly closed by the remote host\n",
      "Exception in callback BaseSelectorEventLoop._read_from_self()\n",
      "handle: <Handle BaseSelectorEventLoop._read_from_self()>\n",
      "Traceback (most recent call last):\n",
      "  File \"C:\\Users\\Admin\\anaconda3\\lib\\asyncio\\events.py\", line 81, in _run\n",
      "    self._context.run(self._callback, *self._args)\n",
      "  File \"C:\\Users\\Admin\\anaconda3\\lib\\asyncio\\selector_events.py\", line 120, in _read_from_self\n",
      "    data = self._ssock.recv(4096)\n",
      "ConnectionResetError: [WinError 10054] An existing connection was forcibly closed by the remote host\n",
      "Exception in callback BaseSelectorEventLoop._read_from_self()\n",
      "handle: <Handle BaseSelectorEventLoop._read_from_self()>\n",
      "Traceback (most recent call last):\n",
      "  File \"C:\\Users\\Admin\\anaconda3\\lib\\asyncio\\events.py\", line 81, in _run\n",
      "    self._context.run(self._callback, *self._args)\n",
      "  File \"C:\\Users\\Admin\\anaconda3\\lib\\asyncio\\selector_events.py\", line 120, in _read_from_self\n",
      "    data = self._ssock.recv(4096)\n",
      "ConnectionResetError: [WinError 10054] An existing connection was forcibly closed by the remote host\n",
      "Exception in callback BaseSelectorEventLoop._read_from_self()\n",
      "handle: <Handle BaseSelectorEventLoop._read_from_self()>\n",
      "Traceback (most recent call last):\n",
      "  File \"C:\\Users\\Admin\\anaconda3\\lib\\asyncio\\events.py\", line 81, in _run\n",
      "    self._context.run(self._callback, *self._args)\n",
      "  File \"C:\\Users\\Admin\\anaconda3\\lib\\asyncio\\selector_events.py\", line 120, in _read_from_self\n",
      "    data = self._ssock.recv(4096)\n",
      "ConnectionResetError: [WinError 10054] An existing connection was forcibly closed by the remote host\n",
      "Exception in callback BaseSelectorEventLoop._read_from_self()\n",
      "handle: <Handle BaseSelectorEventLoop._read_from_self()>\n",
      "Traceback (most recent call last):\n",
      "  File \"C:\\Users\\Admin\\anaconda3\\lib\\asyncio\\events.py\", line 81, in _run\n",
      "    self._context.run(self._callback, *self._args)\n",
      "  File \"C:\\Users\\Admin\\anaconda3\\lib\\asyncio\\selector_events.py\", line 120, in _read_from_self\n",
      "    data = self._ssock.recv(4096)\n",
      "ConnectionResetError: [WinError 10054] An existing connection was forcibly closed by the remote host\n",
      "Exception in callback BaseSelectorEventLoop._read_from_self()\n",
      "handle: <Handle BaseSelectorEventLoop._read_from_self()>\n",
      "Traceback (most recent call last):\n",
      "  File \"C:\\Users\\Admin\\anaconda3\\lib\\asyncio\\events.py\", line 81, in _run\n",
      "    self._context.run(self._callback, *self._args)\n",
      "  File \"C:\\Users\\Admin\\anaconda3\\lib\\asyncio\\selector_events.py\", line 120, in _read_from_self\n",
      "    data = self._ssock.recv(4096)\n",
      "ConnectionResetError: [WinError 10054] An existing connection was forcibly closed by the remote host\n",
      "Exception in callback BaseSelectorEventLoop._read_from_self()\n",
      "handle: <Handle BaseSelectorEventLoop._read_from_self()>\n",
      "Traceback (most recent call last):\n",
      "  File \"C:\\Users\\Admin\\anaconda3\\lib\\asyncio\\events.py\", line 81, in _run\n",
      "    self._context.run(self._callback, *self._args)\n",
      "  File \"C:\\Users\\Admin\\anaconda3\\lib\\asyncio\\selector_events.py\", line 120, in _read_from_self\n",
      "    data = self._ssock.recv(4096)\n",
      "ConnectionResetError: [WinError 10054] An existing connection was forcibly closed by the remote host\n",
      "Exception in callback BaseSelectorEventLoop._read_from_self()\n",
      "handle: <Handle BaseSelectorEventLoop._read_from_self()>\n",
      "Traceback (most recent call last):\n",
      "  File \"C:\\Users\\Admin\\anaconda3\\lib\\asyncio\\events.py\", line 81, in _run\n",
      "    self._context.run(self._callback, *self._args)\n",
      "  File \"C:\\Users\\Admin\\anaconda3\\lib\\asyncio\\selector_events.py\", line 120, in _read_from_self\n",
      "    data = self._ssock.recv(4096)\n",
      "ConnectionResetError: [WinError 10054] An existing connection was forcibly closed by the remote host\n",
      "Exception in callback BaseSelectorEventLoop._read_from_self()\n",
      "handle: <Handle BaseSelectorEventLoop._read_from_self()>\n",
      "Traceback (most recent call last):\n",
      "  File \"C:\\Users\\Admin\\anaconda3\\lib\\asyncio\\events.py\", line 81, in _run\n",
      "    self._context.run(self._callback, *self._args)\n",
      "  File \"C:\\Users\\Admin\\anaconda3\\lib\\asyncio\\selector_events.py\", line 120, in _read_from_self\n",
      "    data = self._ssock.recv(4096)\n",
      "ConnectionResetError: [WinError 10054] An existing connection was forcibly closed by the remote host\n",
      "Exception in callback BaseSelectorEventLoop._read_from_self()\n",
      "handle: <Handle BaseSelectorEventLoop._read_from_self()>\n",
      "Traceback (most recent call last):\n",
      "  File \"C:\\Users\\Admin\\anaconda3\\lib\\asyncio\\events.py\", line 81, in _run\n",
      "    self._context.run(self._callback, *self._args)\n",
      "  File \"C:\\Users\\Admin\\anaconda3\\lib\\asyncio\\selector_events.py\", line 120, in _read_from_self\n",
      "    data = self._ssock.recv(4096)\n",
      "ConnectionResetError: [WinError 10054] An existing connection was forcibly closed by the remote host\n",
      "Exception in callback BaseSelectorEventLoop._read_from_self()\n",
      "handle: <Handle BaseSelectorEventLoop._read_from_self()>\n",
      "Traceback (most recent call last):\n",
      "  File \"C:\\Users\\Admin\\anaconda3\\lib\\asyncio\\events.py\", line 81, in _run\n",
      "    self._context.run(self._callback, *self._args)\n",
      "  File \"C:\\Users\\Admin\\anaconda3\\lib\\asyncio\\selector_events.py\", line 120, in _read_from_self\n",
      "    data = self._ssock.recv(4096)\n",
      "ConnectionResetError: [WinError 10054] An existing connection was forcibly closed by the remote host\n",
      "Exception in callback BaseSelectorEventLoop._read_from_self()\n",
      "handle: <Handle BaseSelectorEventLoop._read_from_self()>\n",
      "Traceback (most recent call last):\n",
      "  File \"C:\\Users\\Admin\\anaconda3\\lib\\asyncio\\events.py\", line 81, in _run\n",
      "    self._context.run(self._callback, *self._args)\n",
      "  File \"C:\\Users\\Admin\\anaconda3\\lib\\asyncio\\selector_events.py\", line 120, in _read_from_self\n",
      "    data = self._ssock.recv(4096)\n",
      "ConnectionResetError: [WinError 10054] An existing connection was forcibly closed by the remote host\n",
      "Exception in callback BaseSelectorEventLoop._read_from_self()\n",
      "handle: <Handle BaseSelectorEventLoop._read_from_self()>\n",
      "Traceback (most recent call last):\n",
      "  File \"C:\\Users\\Admin\\anaconda3\\lib\\asyncio\\events.py\", line 81, in _run\n",
      "    self._context.run(self._callback, *self._args)\n",
      "  File \"C:\\Users\\Admin\\anaconda3\\lib\\asyncio\\selector_events.py\", line 120, in _read_from_self\n",
      "    data = self._ssock.recv(4096)\n",
      "ConnectionResetError: [WinError 10054] An existing connection was forcibly closed by the remote host\n",
      "Exception in callback BaseSelectorEventLoop._read_from_self()\n",
      "handle: <Handle BaseSelectorEventLoop._read_from_self()>\n",
      "Traceback (most recent call last):\n",
      "  File \"C:\\Users\\Admin\\anaconda3\\lib\\asyncio\\events.py\", line 81, in _run\n",
      "    self._context.run(self._callback, *self._args)\n",
      "  File \"C:\\Users\\Admin\\anaconda3\\lib\\asyncio\\selector_events.py\", line 120, in _read_from_self\n",
      "    data = self._ssock.recv(4096)\n",
      "ConnectionResetError: [WinError 10054] An existing connection was forcibly closed by the remote host\n"
     ]
    },
    {
     "name": "stderr",
     "output_type": "stream",
     "text": [
      "Exception in callback BaseSelectorEventLoop._read_from_self()\n",
      "handle: <Handle BaseSelectorEventLoop._read_from_self()>\n",
      "Traceback (most recent call last):\n",
      "  File \"C:\\Users\\Admin\\anaconda3\\lib\\asyncio\\events.py\", line 81, in _run\n",
      "    self._context.run(self._callback, *self._args)\n",
      "  File \"C:\\Users\\Admin\\anaconda3\\lib\\asyncio\\selector_events.py\", line 120, in _read_from_self\n",
      "    data = self._ssock.recv(4096)\n",
      "ConnectionResetError: [WinError 10054] An existing connection was forcibly closed by the remote host\n",
      "Exception in callback BaseSelectorEventLoop._read_from_self()\n",
      "handle: <Handle BaseSelectorEventLoop._read_from_self()>\n",
      "Traceback (most recent call last):\n",
      "  File \"C:\\Users\\Admin\\anaconda3\\lib\\asyncio\\events.py\", line 81, in _run\n",
      "    self._context.run(self._callback, *self._args)\n",
      "  File \"C:\\Users\\Admin\\anaconda3\\lib\\asyncio\\selector_events.py\", line 120, in _read_from_self\n",
      "    data = self._ssock.recv(4096)\n",
      "ConnectionResetError: [WinError 10054] An existing connection was forcibly closed by the remote host\n",
      "Exception in callback BaseSelectorEventLoop._read_from_self()\n",
      "handle: <Handle BaseSelectorEventLoop._read_from_self()>\n",
      "Traceback (most recent call last):\n",
      "  File \"C:\\Users\\Admin\\anaconda3\\lib\\asyncio\\events.py\", line 81, in _run\n",
      "    self._context.run(self._callback, *self._args)\n",
      "  File \"C:\\Users\\Admin\\anaconda3\\lib\\asyncio\\selector_events.py\", line 120, in _read_from_self\n",
      "    data = self._ssock.recv(4096)\n",
      "ConnectionResetError: [WinError 10054] An existing connection was forcibly closed by the remote host\n",
      "Exception in callback BaseSelectorEventLoop._read_from_self()\n",
      "handle: <Handle BaseSelectorEventLoop._read_from_self()>\n",
      "Traceback (most recent call last):\n",
      "  File \"C:\\Users\\Admin\\anaconda3\\lib\\asyncio\\events.py\", line 81, in _run\n",
      "    self._context.run(self._callback, *self._args)\n",
      "  File \"C:\\Users\\Admin\\anaconda3\\lib\\asyncio\\selector_events.py\", line 120, in _read_from_self\n",
      "    data = self._ssock.recv(4096)\n",
      "ConnectionResetError: [WinError 10054] An existing connection was forcibly closed by the remote host\n",
      "Exception in callback BaseSelectorEventLoop._read_from_self()\n",
      "handle: <Handle BaseSelectorEventLoop._read_from_self()>\n",
      "Traceback (most recent call last):\n",
      "  File \"C:\\Users\\Admin\\anaconda3\\lib\\asyncio\\events.py\", line 81, in _run\n",
      "    self._context.run(self._callback, *self._args)\n",
      "  File \"C:\\Users\\Admin\\anaconda3\\lib\\asyncio\\selector_events.py\", line 120, in _read_from_self\n",
      "    data = self._ssock.recv(4096)\n",
      "ConnectionResetError: [WinError 10054] An existing connection was forcibly closed by the remote host\n",
      "Exception in callback BaseSelectorEventLoop._read_from_self()\n",
      "handle: <Handle BaseSelectorEventLoop._read_from_self()>\n",
      "Traceback (most recent call last):\n",
      "  File \"C:\\Users\\Admin\\anaconda3\\lib\\asyncio\\events.py\", line 81, in _run\n",
      "    self._context.run(self._callback, *self._args)\n",
      "  File \"C:\\Users\\Admin\\anaconda3\\lib\\asyncio\\selector_events.py\", line 120, in _read_from_self\n",
      "    data = self._ssock.recv(4096)\n",
      "ConnectionResetError: [WinError 10054] An existing connection was forcibly closed by the remote host\n",
      "Exception in callback BaseSelectorEventLoop._read_from_self()\n",
      "handle: <Handle BaseSelectorEventLoop._read_from_self()>\n",
      "Traceback (most recent call last):\n",
      "  File \"C:\\Users\\Admin\\anaconda3\\lib\\asyncio\\events.py\", line 81, in _run\n",
      "    self._context.run(self._callback, *self._args)\n",
      "  File \"C:\\Users\\Admin\\anaconda3\\lib\\asyncio\\selector_events.py\", line 120, in _read_from_self\n",
      "    data = self._ssock.recv(4096)\n",
      "ConnectionResetError: [WinError 10054] An existing connection was forcibly closed by the remote host\n",
      "Exception in callback BaseSelectorEventLoop._read_from_self()\n",
      "handle: <Handle BaseSelectorEventLoop._read_from_self()>\n",
      "Traceback (most recent call last):\n",
      "  File \"C:\\Users\\Admin\\anaconda3\\lib\\asyncio\\events.py\", line 81, in _run\n",
      "    self._context.run(self._callback, *self._args)\n",
      "  File \"C:\\Users\\Admin\\anaconda3\\lib\\asyncio\\selector_events.py\", line 120, in _read_from_self\n",
      "    data = self._ssock.recv(4096)\n",
      "ConnectionResetError: [WinError 10054] An existing connection was forcibly closed by the remote host\n",
      "Exception in callback BaseSelectorEventLoop._read_from_self()\n",
      "handle: <Handle BaseSelectorEventLoop._read_from_self()>\n",
      "Traceback (most recent call last):\n",
      "  File \"C:\\Users\\Admin\\anaconda3\\lib\\asyncio\\events.py\", line 81, in _run\n",
      "    self._context.run(self._callback, *self._args)\n",
      "  File \"C:\\Users\\Admin\\anaconda3\\lib\\asyncio\\selector_events.py\", line 120, in _read_from_self\n",
      "    data = self._ssock.recv(4096)\n",
      "ConnectionResetError: [WinError 10054] An existing connection was forcibly closed by the remote host\n",
      "Exception in callback BaseSelectorEventLoop._read_from_self()\n",
      "handle: <Handle BaseSelectorEventLoop._read_from_self()>\n",
      "Traceback (most recent call last):\n",
      "  File \"C:\\Users\\Admin\\anaconda3\\lib\\asyncio\\events.py\", line 81, in _run\n",
      "    self._context.run(self._callback, *self._args)\n",
      "  File \"C:\\Users\\Admin\\anaconda3\\lib\\asyncio\\selector_events.py\", line 120, in _read_from_self\n",
      "    data = self._ssock.recv(4096)\n",
      "ConnectionResetError: [WinError 10054] An existing connection was forcibly closed by the remote host\n",
      "Exception in callback BaseSelectorEventLoop._read_from_self()\n",
      "handle: <Handle BaseSelectorEventLoop._read_from_self()>\n",
      "Traceback (most recent call last):\n",
      "  File \"C:\\Users\\Admin\\anaconda3\\lib\\asyncio\\events.py\", line 81, in _run\n",
      "    self._context.run(self._callback, *self._args)\n",
      "  File \"C:\\Users\\Admin\\anaconda3\\lib\\asyncio\\selector_events.py\", line 120, in _read_from_self\n",
      "    data = self._ssock.recv(4096)\n",
      "ConnectionResetError: [WinError 10054] An existing connection was forcibly closed by the remote host\n",
      "Exception in callback BaseSelectorEventLoop._read_from_self()\n",
      "handle: <Handle BaseSelectorEventLoop._read_from_self()>\n",
      "Traceback (most recent call last):\n",
      "  File \"C:\\Users\\Admin\\anaconda3\\lib\\asyncio\\events.py\", line 81, in _run\n",
      "    self._context.run(self._callback, *self._args)\n",
      "  File \"C:\\Users\\Admin\\anaconda3\\lib\\asyncio\\selector_events.py\", line 120, in _read_from_self\n",
      "    data = self._ssock.recv(4096)\n",
      "ConnectionResetError: [WinError 10054] An existing connection was forcibly closed by the remote host\n",
      "Exception in callback BaseSelectorEventLoop._read_from_self()\n",
      "handle: <Handle BaseSelectorEventLoop._read_from_self()>\n",
      "Traceback (most recent call last):\n",
      "  File \"C:\\Users\\Admin\\anaconda3\\lib\\asyncio\\events.py\", line 81, in _run\n",
      "    self._context.run(self._callback, *self._args)\n",
      "  File \"C:\\Users\\Admin\\anaconda3\\lib\\asyncio\\selector_events.py\", line 120, in _read_from_self\n",
      "    data = self._ssock.recv(4096)\n",
      "ConnectionResetError: [WinError 10054] An existing connection was forcibly closed by the remote host\n",
      "Exception in callback BaseSelectorEventLoop._read_from_self()\n",
      "handle: <Handle BaseSelectorEventLoop._read_from_self()>\n",
      "Traceback (most recent call last):\n",
      "  File \"C:\\Users\\Admin\\anaconda3\\lib\\asyncio\\events.py\", line 81, in _run\n",
      "    self._context.run(self._callback, *self._args)\n",
      "  File \"C:\\Users\\Admin\\anaconda3\\lib\\asyncio\\selector_events.py\", line 120, in _read_from_self\n",
      "    data = self._ssock.recv(4096)\n",
      "ConnectionResetError: [WinError 10054] An existing connection was forcibly closed by the remote host\n",
      "Exception in callback BaseSelectorEventLoop._read_from_self()\n",
      "handle: <Handle BaseSelectorEventLoop._read_from_self()>\n",
      "Traceback (most recent call last):\n",
      "  File \"C:\\Users\\Admin\\anaconda3\\lib\\asyncio\\events.py\", line 81, in _run\n",
      "    self._context.run(self._callback, *self._args)\n",
      "  File \"C:\\Users\\Admin\\anaconda3\\lib\\asyncio\\selector_events.py\", line 120, in _read_from_self\n",
      "    data = self._ssock.recv(4096)\n",
      "ConnectionResetError: [WinError 10054] An existing connection was forcibly closed by the remote host\n",
      "Exception in callback BaseSelectorEventLoop._read_from_self()\n",
      "handle: <Handle BaseSelectorEventLoop._read_from_self()>\n",
      "Traceback (most recent call last):\n",
      "  File \"C:\\Users\\Admin\\anaconda3\\lib\\asyncio\\events.py\", line 81, in _run\n",
      "    self._context.run(self._callback, *self._args)\n",
      "  File \"C:\\Users\\Admin\\anaconda3\\lib\\asyncio\\selector_events.py\", line 120, in _read_from_self\n",
      "    data = self._ssock.recv(4096)\n",
      "ConnectionResetError: [WinError 10054] An existing connection was forcibly closed by the remote host\n",
      "Exception in callback BaseSelectorEventLoop._read_from_self()\n",
      "handle: <Handle BaseSelectorEventLoop._read_from_self()>\n",
      "Traceback (most recent call last):\n",
      "  File \"C:\\Users\\Admin\\anaconda3\\lib\\asyncio\\events.py\", line 81, in _run\n",
      "    self._context.run(self._callback, *self._args)\n",
      "  File \"C:\\Users\\Admin\\anaconda3\\lib\\asyncio\\selector_events.py\", line 120, in _read_from_self\n",
      "    data = self._ssock.recv(4096)\n",
      "ConnectionResetError: [WinError 10054] An existing connection was forcibly closed by the remote host\n"
     ]
    },
    {
     "name": "stderr",
     "output_type": "stream",
     "text": [
      "Exception in callback BaseSelectorEventLoop._read_from_self()\n",
      "handle: <Handle BaseSelectorEventLoop._read_from_self()>\n",
      "Traceback (most recent call last):\n",
      "  File \"C:\\Users\\Admin\\anaconda3\\lib\\asyncio\\events.py\", line 81, in _run\n",
      "    self._context.run(self._callback, *self._args)\n",
      "  File \"C:\\Users\\Admin\\anaconda3\\lib\\asyncio\\selector_events.py\", line 120, in _read_from_self\n",
      "    data = self._ssock.recv(4096)\n",
      "ConnectionResetError: [WinError 10054] An existing connection was forcibly closed by the remote host\n",
      "Exception in callback BaseSelectorEventLoop._read_from_self()\n",
      "handle: <Handle BaseSelectorEventLoop._read_from_self()>\n",
      "Traceback (most recent call last):\n",
      "  File \"C:\\Users\\Admin\\anaconda3\\lib\\asyncio\\events.py\", line 81, in _run\n",
      "    self._context.run(self._callback, *self._args)\n",
      "  File \"C:\\Users\\Admin\\anaconda3\\lib\\asyncio\\selector_events.py\", line 120, in _read_from_self\n",
      "    data = self._ssock.recv(4096)\n",
      "ConnectionResetError: [WinError 10054] An existing connection was forcibly closed by the remote host\n",
      "Exception in callback BaseSelectorEventLoop._read_from_self()\n",
      "handle: <Handle BaseSelectorEventLoop._read_from_self()>\n",
      "Traceback (most recent call last):\n",
      "  File \"C:\\Users\\Admin\\anaconda3\\lib\\asyncio\\events.py\", line 81, in _run\n",
      "    self._context.run(self._callback, *self._args)\n",
      "  File \"C:\\Users\\Admin\\anaconda3\\lib\\asyncio\\selector_events.py\", line 120, in _read_from_self\n",
      "    data = self._ssock.recv(4096)\n",
      "ConnectionResetError: [WinError 10054] An existing connection was forcibly closed by the remote host\n",
      "Exception in callback BaseSelectorEventLoop._read_from_self()\n",
      "handle: <Handle BaseSelectorEventLoop._read_from_self()>\n",
      "Traceback (most recent call last):\n",
      "  File \"C:\\Users\\Admin\\anaconda3\\lib\\asyncio\\events.py\", line 81, in _run\n",
      "    self._context.run(self._callback, *self._args)\n",
      "  File \"C:\\Users\\Admin\\anaconda3\\lib\\asyncio\\selector_events.py\", line 120, in _read_from_self\n",
      "    data = self._ssock.recv(4096)\n",
      "ConnectionResetError: [WinError 10054] An existing connection was forcibly closed by the remote host\n",
      "Exception in callback BaseSelectorEventLoop._read_from_self()\n",
      "handle: <Handle BaseSelectorEventLoop._read_from_self()>\n",
      "Traceback (most recent call last):\n",
      "  File \"C:\\Users\\Admin\\anaconda3\\lib\\asyncio\\events.py\", line 81, in _run\n",
      "    self._context.run(self._callback, *self._args)\n",
      "  File \"C:\\Users\\Admin\\anaconda3\\lib\\asyncio\\selector_events.py\", line 120, in _read_from_self\n",
      "    data = self._ssock.recv(4096)\n",
      "ConnectionResetError: [WinError 10054] An existing connection was forcibly closed by the remote host\n",
      "Exception in callback BaseSelectorEventLoop._read_from_self()\n",
      "handle: <Handle BaseSelectorEventLoop._read_from_self()>\n",
      "Traceback (most recent call last):\n",
      "  File \"C:\\Users\\Admin\\anaconda3\\lib\\asyncio\\events.py\", line 81, in _run\n",
      "    self._context.run(self._callback, *self._args)\n",
      "  File \"C:\\Users\\Admin\\anaconda3\\lib\\asyncio\\selector_events.py\", line 120, in _read_from_self\n",
      "    data = self._ssock.recv(4096)\n",
      "ConnectionResetError: [WinError 10054] An existing connection was forcibly closed by the remote host\n",
      "Exception in callback BaseSelectorEventLoop._read_from_self()\n",
      "handle: <Handle BaseSelectorEventLoop._read_from_self()>\n",
      "Traceback (most recent call last):\n",
      "  File \"C:\\Users\\Admin\\anaconda3\\lib\\asyncio\\events.py\", line 81, in _run\n",
      "    self._context.run(self._callback, *self._args)\n",
      "  File \"C:\\Users\\Admin\\anaconda3\\lib\\asyncio\\selector_events.py\", line 120, in _read_from_self\n",
      "    data = self._ssock.recv(4096)\n",
      "ConnectionResetError: [WinError 10054] An existing connection was forcibly closed by the remote host\n",
      "Exception in callback BaseSelectorEventLoop._read_from_self()\n",
      "handle: <Handle BaseSelectorEventLoop._read_from_self()>\n",
      "Traceback (most recent call last):\n",
      "  File \"C:\\Users\\Admin\\anaconda3\\lib\\asyncio\\events.py\", line 81, in _run\n",
      "    self._context.run(self._callback, *self._args)\n",
      "  File \"C:\\Users\\Admin\\anaconda3\\lib\\asyncio\\selector_events.py\", line 120, in _read_from_self\n",
      "    data = self._ssock.recv(4096)\n",
      "ConnectionResetError: [WinError 10054] An existing connection was forcibly closed by the remote host\n",
      "Exception in callback BaseSelectorEventLoop._read_from_self()\n",
      "handle: <Handle BaseSelectorEventLoop._read_from_self()>\n",
      "Traceback (most recent call last):\n",
      "  File \"C:\\Users\\Admin\\anaconda3\\lib\\asyncio\\events.py\", line 81, in _run\n",
      "    self._context.run(self._callback, *self._args)\n",
      "  File \"C:\\Users\\Admin\\anaconda3\\lib\\asyncio\\selector_events.py\", line 120, in _read_from_self\n",
      "    data = self._ssock.recv(4096)\n",
      "ConnectionResetError: [WinError 10054] An existing connection was forcibly closed by the remote host\n",
      "Exception in callback BaseSelectorEventLoop._read_from_self()\n",
      "handle: <Handle BaseSelectorEventLoop._read_from_self()>\n",
      "Traceback (most recent call last):\n",
      "  File \"C:\\Users\\Admin\\anaconda3\\lib\\asyncio\\events.py\", line 81, in _run\n",
      "    self._context.run(self._callback, *self._args)\n",
      "  File \"C:\\Users\\Admin\\anaconda3\\lib\\asyncio\\selector_events.py\", line 120, in _read_from_self\n",
      "    data = self._ssock.recv(4096)\n",
      "ConnectionResetError: [WinError 10054] An existing connection was forcibly closed by the remote host\n",
      "Exception in callback BaseSelectorEventLoop._read_from_self()\n",
      "handle: <Handle BaseSelectorEventLoop._read_from_self()>\n",
      "Traceback (most recent call last):\n",
      "  File \"C:\\Users\\Admin\\anaconda3\\lib\\asyncio\\events.py\", line 81, in _run\n",
      "    self._context.run(self._callback, *self._args)\n",
      "  File \"C:\\Users\\Admin\\anaconda3\\lib\\asyncio\\selector_events.py\", line 120, in _read_from_self\n",
      "    data = self._ssock.recv(4096)\n",
      "ConnectionResetError: [WinError 10054] An existing connection was forcibly closed by the remote host\n",
      "Exception in callback BaseSelectorEventLoop._read_from_self()\n",
      "handle: <Handle BaseSelectorEventLoop._read_from_self()>\n",
      "Traceback (most recent call last):\n",
      "  File \"C:\\Users\\Admin\\anaconda3\\lib\\asyncio\\events.py\", line 81, in _run\n",
      "    self._context.run(self._callback, *self._args)\n",
      "  File \"C:\\Users\\Admin\\anaconda3\\lib\\asyncio\\selector_events.py\", line 120, in _read_from_self\n",
      "    data = self._ssock.recv(4096)\n",
      "ConnectionResetError: [WinError 10054] An existing connection was forcibly closed by the remote host\n",
      "Exception in callback BaseSelectorEventLoop._read_from_self()\n",
      "handle: <Handle BaseSelectorEventLoop._read_from_self()>\n",
      "Traceback (most recent call last):\n",
      "  File \"C:\\Users\\Admin\\anaconda3\\lib\\asyncio\\events.py\", line 81, in _run\n",
      "    self._context.run(self._callback, *self._args)\n",
      "  File \"C:\\Users\\Admin\\anaconda3\\lib\\asyncio\\selector_events.py\", line 120, in _read_from_self\n",
      "    data = self._ssock.recv(4096)\n",
      "ConnectionResetError: [WinError 10054] An existing connection was forcibly closed by the remote host\n",
      "Exception in callback BaseSelectorEventLoop._read_from_self()\n",
      "handle: <Handle BaseSelectorEventLoop._read_from_self()>\n",
      "Traceback (most recent call last):\n",
      "  File \"C:\\Users\\Admin\\anaconda3\\lib\\asyncio\\events.py\", line 81, in _run\n",
      "    self._context.run(self._callback, *self._args)\n",
      "  File \"C:\\Users\\Admin\\anaconda3\\lib\\asyncio\\selector_events.py\", line 120, in _read_from_self\n",
      "    data = self._ssock.recv(4096)\n",
      "ConnectionResetError: [WinError 10054] An existing connection was forcibly closed by the remote host\n",
      "Exception in callback BaseSelectorEventLoop._read_from_self()\n",
      "handle: <Handle BaseSelectorEventLoop._read_from_self()>\n",
      "Traceback (most recent call last):\n",
      "  File \"C:\\Users\\Admin\\anaconda3\\lib\\asyncio\\events.py\", line 81, in _run\n",
      "    self._context.run(self._callback, *self._args)\n",
      "  File \"C:\\Users\\Admin\\anaconda3\\lib\\asyncio\\selector_events.py\", line 120, in _read_from_self\n",
      "    data = self._ssock.recv(4096)\n",
      "ConnectionResetError: [WinError 10054] An existing connection was forcibly closed by the remote host\n",
      "Exception in callback BaseSelectorEventLoop._read_from_self()\n",
      "handle: <Handle BaseSelectorEventLoop._read_from_self()>\n",
      "Traceback (most recent call last):\n",
      "  File \"C:\\Users\\Admin\\anaconda3\\lib\\asyncio\\events.py\", line 81, in _run\n",
      "    self._context.run(self._callback, *self._args)\n",
      "  File \"C:\\Users\\Admin\\anaconda3\\lib\\asyncio\\selector_events.py\", line 120, in _read_from_self\n",
      "    data = self._ssock.recv(4096)\n",
      "ConnectionResetError: [WinError 10054] An existing connection was forcibly closed by the remote host\n"
     ]
    }
   ],
   "source": [
    "df = h2o.import_file(\"C:/Users/User/Desktop/cdac advance modules/pml lecture/class  practice/program_dataset/Sonar.csv\")\n",
    "#df.summary()\n",
    "df.col_names"
   ]
  },
  {
   "cell_type": "code",
   "execution_count": null,
   "id": "dd9a9bd4",
   "metadata": {},
   "outputs": [],
   "source": [
    "\n",
    "y_col = 'Class'\n",
    "x_cols = df.col_names[:60]\n",
    "#x.remove(y)\n",
    "#x.remove('ID')\n",
    "print(\"Response = \" + y_col)\n",
    "print(\"Pridictors = \" + str(x_cols))\n",
    "\n",
    "df['Class'] = df['Class'].asfactor()\n",
    "df['Class'].levels()\n",
    "\n",
    "train,  test = df.split_frame(ratios=[.8])\n",
    "print(df.shape)\n",
    "print(train.shape)\n",
    "#print(valid.shape)\n",
    "print(test.shape)\n",
    "\n",
    "from h2o.estimators.glm import H2OGeneralizedLinearEstimator\n",
    "glm_logistic = H2OGeneralizedLinearEstimator(family = \"binomial\")\n",
    "glm_logistic.train(x=x_cols, y=y_col, training_frame=train, \n",
    "                   validation_frame=test, model_id=\"glm_logistic\")\n",
    "\n",
    "y_pred = glm_logistic.predict(test_data=test)\n",
    "\n",
    "y_pred_df = y_pred.as_data_frame()\n",
    "\n",
    "print(glm_logistic.auc() )\n",
    "print(glm_logistic.confusion_matrix() )\n",
    "h2o.cluster().shutdown()"
   ]
  }
 ],
 "metadata": {
  "kernelspec": {
   "display_name": "Python 3",
   "language": "python",
   "name": "python3"
  },
  "language_info": {
   "codemirror_mode": {
    "name": "ipython",
    "version": 3
   },
   "file_extension": ".py",
   "mimetype": "text/x-python",
   "name": "python",
   "nbconvert_exporter": "python",
   "pygments_lexer": "ipython3",
   "version": "3.8.8"
  }
 },
 "nbformat": 4,
 "nbformat_minor": 5
}
